Workbook
Name TS_DA_SO: '_bk 0805-0059 ⚙️ Tham số'!$C$4
Name TS_TS_VH2: '_bk 0830-1613 ⚙️ Tham số'!$C$16
Name TS_TUT_TOI_DA: '_bk 0807-2143 ⚙️ Tham số'!$C$5
Name TS_NG_BAC: '_bk 0823-2357 ⚙️ Tham số'!$C$6
Name TS_TUT_TOI_DA: '_bk 0805-0113 ⚙️ Tham số'!$C$5
Name TS_NG3: '_bk 0830-1529 ⚙️ Tham số'!$C$10
Name NR_NG_BAC: '_bk 0816-0145 ⚙️ Tham số'!$F$8:$F$12
Name NR_NGUONG_TL: #REF!
Name TS_NG1: '_bk 0830-1613 ⚙️ Tham số'!$C$8
Name TS_PM_ID: '_bk 0830-0410 ⚙️ Tham số'!$C$15
Name NR_DOT_MO: '👥 Nhân sự'!$B$2
Name TS_NG2: '_bk 0807-2133 ⚙️ Tham số'!$C$8
Name NR_NG_TL: '_bk 0830-0410 ⚙️ Tham số'!$C$8:$C$12
Name TS_NG1: '_bk 0809-2346 ⚙️ Tham số'!$C$8
Name TS_DA_SO: '_bk 0824-0030 ⚙️ Tham số'!$C$4
Name TS_NG1: '_bk 0824-0030 ⚙️ Tham số'!$C$8
Name TS_NG3: '_bk 0819-1251 ⚙️ Tham số'!$C$10
Name NR_NG_BAC: '_bk 0809-1844 ⚙️ Tham số'!$F$7:$F$11
Name TS_TS_QL2: '_bk 0830-1529 ⚙️ Tham số'!$C$17
Name TS_TS_CHUYENMON: #REF!
Name NR_NG_TL: '_bk 0904-0304 ⚙️ Tham số'!$C$8:$C$12
Name TS_NG_BAC: '_bk 0831-1630 ⚙️ Tham số'!$C$6
Name TS_NG5: '_bk 0803-1322 ⚙️ Tham số'!$C$13
Name TS_NG3: '_bk 0807-2143 ⚙️ Tham số'!$C$9
Name TS_TS_VANHOA: '_bk 0803-1322 ⚙️ Tham số'!$C$7
Name TS_NG_BAC: '_bk 0816-0145 ⚙️ Tham số'!$C$6
Name TS_DRIVE_ID: '_bk 0807-2234 ⚙️ Tham số'!$C$13
Name TS_NG5: '_bk 0830-0822 ⚙️ Tham số'!$C$12
Name TS_NG1: '_bk 0805-0113 ⚙️ Tham số'!$C$9
Name TS_NG5: '_bk 0816-0145 ⚙️ Tham số'!$C$12
Name NR_DOT_MO: '_bk 0809-1844 👥 Nhân sự'!$B$2
Name TS_TS_QL2: '_bk 0830-1613 ⚙️ Tham số'!$C$17
Name TS_PM_ID: '_bk 0811-0352 ⚙️ Tham số'!$C$15
Name TS_NG4: '_bk 0819-1251 ⚙️ Tham số'!$C$11
Name TS_TS_VH1: '_bk 0830-1613 ⚙️ Tham số'!$C$14
Name NR_NG_BAC: '_bk 0809-2346 ⚙️ Tham số'!$F$8:$F$12
Name TS_NG_BAC: '_bk 0823-2344 ⚙️ Tham số'!$C$6
Name NR_DOT_MO: '_bk 0830-0822 👥 Nhân sự'!$B$2
Name TS_TUT_TOI_DA: '⚙️ Tham số'!$C$5
Name NR_NG_TL: '_bk 0807-1445 ⚙️ Tham số'!$C$7:$C$11
Name TS_TS_CM2: '_bk 0830-0822 ⚙️ Tham số'!$C$18
Name TS_DRIVE_ID: '_bk 0819-1251 ⚙️ Tham số'!$C$14
Name TS_PM_ID: '_bk 0830-1728 ⚙️ Tham số'!$C$21
Name TS_PM_ID: '_bk 0805-0113 ⚙️ Tham số'!$C$16
Name NR_NG_TL: '_bk 0803-1322 ⚙️ Tham số'!$C$9:$C$13
Name TS_NG2: '_bk 0807-2234 ⚙️ Tham số'!$C$8
Name TS_TRAN_CN: #REF!
Name TS_NG3: '_bk 0904-0304 ⚙️ Tham số'!$C$10
Name TS_DRIVE_ID: '_bk 0807-2133 ⚙️ Tham số'!$C$13
Name NR_NG_BAC: '_bk 0830-1529 ⚙️ Tham số'!$F$8:$F$12
Name TS_NG3: '_bk 0807-1423 ⚙️ Tham số'!$C$9
Name TS_NG3: '_bk 0807-2234 ⚙️ Tham số'!$C$9
Name TS_TS_VANHOA: '_bk 0805-0113 ⚙️ Tham số'!$C$7
Name TS_NG5: '_bk 0816-0136 ⚙️ Tham số'!$C$12
Name TS_NG1: '_bk 0816-0136 ⚙️ Tham số'!$C$8
Name TS_PM_ID: '_bk 0824-0030 ⚙️ Tham số'!$C$15
Name TS_NG_BAC: '_bk 0809-2346 ⚙️ Tham số'!$C$6
Name TS_DA_SO: '_bk 0807-1423 ⚙️ Tham số'!$C$4
Name TS_NG4: '_bk 0811-0322 ⚙️ Tham số'!$C$11
Name NR_NG_TL: '_bk 0816-0145 ⚙️ Tham số'!$C$8:$C$12

Sheet 📖 Hướng dẫn
A1: 📖 HƯỚNG DẪN VẬN HÀNH HỆ ĐÁNH GIÁ NHÂN SỰ - Công ty TNHH Nhà Của Thời Thanh Xuân · Phòng Nhân sự - Hành chính - Pháp chế · Phiên bản 6.3 · 4/9/2026, điểm nền ra sheet riêng, sửa đường di cư dòng
A3: I. ĐÂY LÀ FILE GÌ
A4: File gốc | B4: Bảng tính bạn đang mở là FILE GỐC. Nó giữ code, tham số, khung chung, và ma trận cấp bậc kèm giải thích của tất cả các tuyến, mỗi tuyến một sheet. KHÔNG chấm điểm trên file này.
A5: File năm | B5: Mỗi người có ĐÚNG MỘT file cho cả năm, mười hai sheet tháng T01 tới T12 lập sẵn ngay từ lúc tạo. Chốt điểm tháng này xong thì sang tab kế bên, không tạo file mới và không đổi link. File năm không chứa code, nhưng mang theo sheet ma trận và khung chung của tuyến đó.
A6: Vì sao tách hai loại file | B6: Một, mỗi người chỉ thấy file của chính mình, không thấy điểm của người khác. Hai, code nằm một nơi nên sửa một lần là xong, không phải đi sửa hàng chục file.
A7: Ai điền điểm | B7: KHÔNG có người chấm ngồi cân nhắc từng ô. Điểm đầu tháng là mặc định, rồi đi lên đi xuống theo biên bản vi phạm và phiếu ghi nhận mà Phòng Nhân sự - Hành chính - Pháp chế lập. Ứng dụng ghi từng biên bản vào sheet ẩn _log của chính file năm đó.
A8: Điểm mặc định | B8: Nhóm đo VI PHẠM bắt đầu ở 5, tức chưa có biên bản nào. Nhóm đo GHI NHẬN bắt đầu ở 0, tức chưa ghi nhận lần nào. Dòng chữ nhỏ ngay dưới tên mỗi nhóm nói rõ nhóm đó đo chiều nào.
A9: Chiều đo chọn thế nào | B9: Nhóm nêu PHẦN VIỆC ĐƯỢC GIAO thì đo theo chiều vi phạm, vì không làm đúng phần được giao là một lỗi lập được biên bản. Nhóm nêu việc VƯỢT TRÊN phần được giao thì đo theo chiều ghi nhận. Chiều đo khai theo NHÓM, không khai theo từng câu.
A10: Điểm nền của tháng | B10: Điểm nền của một phần chính bằng tỷ lệ câu thuộc nhóm vi phạm của phần đó. Sau đợt 30/8/2026, điểm nền của năm hình dạng phiếu nằm trong khoảng 3,96 tới 4,35 trên thang 5. Bốn hình dạng ra bậc 4, tức hệ số 1,00 đúng bằng mức Công ty dự định trả cho một tháng không có gì xảy ra. Riêng chức năng Nhân sự - Hành chính - Pháp chế cấp quản lý ra bậc 5, xem dòng 2c mục IX.
A12: I b. CHỮ "BẬC" NAY CHỈ CÒN MỘT NGHĨA
A13: Vì sao phải đọc mục này | B13: Tới 30/8/2026 hệ có ba thứ khác hẳn nhau cùng gọi là bậc, và đó là chỗ lẫn nhiều nhất của cả hệ. ✅ CHỐT 31/8/2026 (Sen): chỉ giữ một nghĩa, hai thứ còn lại gọi bằng tên khác.
A14: ĐIỂM, thang 0 tới 5 | B14: Điểm của một câu hỏi. Mặc định đầu tháng là 5 với nhóm đo vi phạm và 0 với nhóm đo ghi nhận, rồi đi lên đi xuống theo biên bản. Gọi là ĐIỂM, không gọi là bậc.
A15: BẬC CÁCH LÀM VIỆC, 1 tới 5 | B15: ⛔ Đây là thứ DUY NHẤT còn được gọi là bậc. ĐI RA từ phiếu mỗi tháng. Điểm tổng tháng quy ra bậc này, rồi tra hệ số 0,10 / 0,40 / 0,90 / 1,00 / 1,10 nhân vào phần P2 của cấp đó. Đây là thứ DUY NHẤT trong phiếu chạm tới tiền hàng tháng. Nhịp NHANH, nâng hạ được trong tháng.
A16: CẤP | B16: Nấc trên con đường thăng tiến, ví dụ Chuyên viên, Lead bộ phận, Trưởng phòng. Trước 31/8/2026 gọi là bậc trong ngạch và ghi bằng số; nay ghi thẳng bằng TÊN. Nguồn duy nhất là 0-Nen-tang/Du-lieu/cap-bac.csv. Nhịp CHẬM, đổi bằng quyết định bổ nhiệm, không đổi theo tháng.
A17: Ngạch Chuyên môn có cấp nào | B17: Tập sự · Nhân viên · Chuyên viên · Chuyên gia. Trần của ngạch là Chuyên gia.
A18: Ngạch Quản lý có cấp nào | B18: Tập sự · Trưởng ca · Lead bộ phận · Quản lý khối · Trưởng phòng · C-Level · Tổng Giám đốc · Người sáng lập.
A19: Hai ngạch so ngang nhau thế nào | B19: Lead bộ phận ngang Chuyên viên, Quản lý khối ngang Chuyên gia: ngang quyền và ngang tiền. Trên nữa chỉ ngạch quản lý còn đi tiếp, tới Trưởng phòng.
A20: ⛔ Ba cấp KHÔNG chấm được | B20: C-Level, Tổng Giám đốc và Người sáng lập xếp bằng quyết định bổ nhiệm và không tụt theo kỳ, nên không đặt ngưỡng ở ba cấp đó.
A21: Đặt ngưỡng cấp cho một câu ở đâu | B21: Ở cột Phạm vi áp dụng của sheet Bộ câu hỏi, ghi "Từ <tên cấp> trở lên", ví dụ "Từ Trưởng phòng trở lên". Đó là cấp THẤP NHẤT mà câu bắt đầu áp dụng. Trên 343 câu hiện có 25 câu đặt ngưỡng, còn lại áp cho mọi người.
A23: II. CÂY THƯ MỤC TRÊN DRIVE
A24: Cấu trúc | B24: <thư mục đang chứa file gốc> / <Năm> / Tuyến <tên> / Đánh giá <Năm> - <Mã nhân sự> - <Họ tên>
A25: Nằm ở đâu | B25: Cây đánh giá nằm NGAY TRONG thư mục đang chứa chính file gốc này, không phải một thư mục riêng ở ngoài. Chuyển file gốc sang thư mục khác thì các năm tạo SAU đó đi theo, còn năm đã tạo TRƯỚC vẫn nằm chỗ cũ và phải kéo tay.
A26: Sắp theo thời gian | B26: Thư mục cấp một là năm nên Drive tự sắp đúng thứ tự thời gian, không cần đánh số tay.
A27: Đổi chỗ thư mục gốc | B27: ĐỂ TRỐNG ô TS_DRIVE_ID là đúng trong hầu hết trường hợp: cây đánh giá tự bám theo thư mục chứa file gốc, nên chuyển file là cây đi theo. Chỉ dán ID vào ô đó khi muốn đặt cây ở một thư mục KHÁC chỗ file gốc đang nằm.
A28: Xem đang nằm ở đâu | B28: Menu 🗂️ Mở thư mục đánh giá chỉ HIỆN tên và đường dẫn thư mục hệ đang dùng. Nó không tạo và không di chuyển gì, bấm bao nhiêu lần cũng không đổi thứ gì.
A30: III. QUY TRÌNH MỘT NĂM
A31: Bước 0 | B31: Menu 🔃 Đồng bộ nhân sự từ People Management. Danh sách nhân sự KHÔNG nhập tay ở đây, nó đọc từ file People Management để hai nơi không giữ hai bản rồi trôi lệch. Sau khi đồng bộ, điền cột Tuyến cho từng người ở sheet 👥 Nhân sự.
A32: Bước 1 | B32: Kiểm tra sheet ⚙️ Tham số xem các ngưỡng và trọng số đã đúng chưa.
A33: Bước 2 | B33: Menu 📅 Tạo file năm cho một người, nhập MÃ NHÂN SỰ. Hoặc 📚 Tạo file năm cho nhiều người, tối đa 6 người một lần. Hệ tự tra tên, vị trí, phòng ban, cấp và tuyến.
A34: Bước 3 | B34: Đưa link file năm cho nhân sự và cho ứng dụng lập biên bản. Trong tháng, mỗi biên bản vi phạm và mỗi phiếu ghi nhận được ứng dụng ghi vào sheet _log và cập nhật ô điểm tương ứng.
A35: Bước 4 | B35: Cuối tháng, đọc khối KẾT QUẢ THÁNG ở đầu sheet tháng đó. Không phải bấm gì, mọi số đều là công thức.
A36: Bước 5 | B36: Menu 📥 Thu kết quả một tháng để dồn kết quả mọi người của tháng đó về sheet 📊 Tổng hợp kỳ. Chạy lại nhiều lần được, dòng cũ của cùng kỳ sẽ bị thay chứ không nhân bản.
A37: Đổi cấp giữa năm | B37: Menu 🔁 Dựng lại các tháng chưa chốt. Nói rõ tháng bắt đầu, các tháng trước giữ nguyên gồm cả điểm đã chốt.
A39: IV. PHIẾU CHO RA MỘT KẾT QUẢ
A40: ⛔ Phiếu nay chỉ cho ra MỘT kết quả | B40: ✅ CHỐT 31/8/2026 (Sen). Hai dòng BẬC TRONG NGẠCH đã bỏ khỏi khối kết quả. Cấp đi qua quyết định bổ nhiệm, không phải thứ một phiếu tháng quyết.
A41: Bậc cách làm việc | B41: Trả lời câu người này LÀM VIỆC THẾ NÀO. Lấy từ ĐIỂM TỔNG THÁNG. Nhịp NHANH, nâng hạ được trong tháng. Đây là kết quả duy nhất của phiếu.
A42: Điểm tổng tháng | B42: Trung bình cộng có trọng số của ba phần. Không giữ vai trò quản lý thì Văn hóa chung 65% và Ngạch chuyên môn 35%. Có giữ vai trò quản lý thì Văn hóa chung 50%, Ngạch quản lý 30%, Ngạch chuyên môn 20%. Năm con số này nằm ở sheet ⚙️ Tham số, mục III.
A43: Không gộp | B43: Cấp và bậc cách làm việc không cộng và không quy đổi cho nhau. Một người có thể được quyết nhiều việc trong khi cách làm việc đang đi xuống, hoặc ngược lại; gộp lại thành một số là xóa mất đúng thông tin cần nhìn.
A44: Từ cấp sang chức danh | B44: Ban lãnh đạo nhìn hai thang chuyên môn và quản lý đang ở đâu rồi tự quyết bổ nhiệm chức danh nào. Phiếu KHÔNG tự quyết việc này.
A45: Từ chức danh sang tiền | B45: Tùy chức danh mà cùng một cấp ra số tiền khác nhau. Bảng đó thuộc quy chế lương, không nằm trong phiếu.
...

Sheet 👥 Nhân sự
A1: 👥 NHÂN SỰ - Đồng bộ từ People Management. Chỉ cột Tuyến là do Công ty gán. Tick ô ▶ để tạo file năm ngay cho người ở dòng đó.
A2: NĂM ĐANG MỞ | B2: 2026 | D2: Đồng bộ lần cuối | G2: Tick ô ▶ là tạo file năm cho người ở dòng đó, gồm mười hai sheet tháng. Danh sách tự đồng bộ mỗi ngày.
A3: Mã NV | B3: Họ tên | C3: ▶ | D3: File năm | E3: Tuyến (gán tay) | F3: Người điếc/ khiếm thính / Người nói | G3: Phòng ban | H3: Vị trí theo Danh mục | I3: Điểm làm việc | J3: Ngày vào làm | K3: Trạng thái | L3: Số lần đã đánh giá | M3: Kỳ gần nhất | N3: Kết quả gần nhất
A4: TTX001 | B4: Võ Thành Luân | C4: FALSE | F4: Người sáng lập - Chủ tịch | G4: Founder - Chairman | H4: Founder | I4: Người nói | J4: Văn phòng | K4: Founder | L4: =COUNTIF('🗂️ Lịch sử đánh giá'!$A:$A,$A4) -> 0 | M4: {=IFERROR(INDEX('🗂️ Lịch sử đánh giá'!$C:$C,MATCH(2,1/('🗂️ Lịch sử đánh giá'!$A:$A=$A4))),"")} | N4: {=IFERROR("CM "&INDEX('🗂️ Lịch sử đánh giá'!$F:$F,MATCH(2,1/('🗂️ Lịch sử đánh giá'!$A:$A=$A4)))&" · QL "&INDEX('🗂️ Lịch sử đánh giá'!$G:$G,MATCH(2,1/('🗂️ Lịch sử đánh giá'!$A:$A=$A4)))&" · CLV "&INDEX('🗂️ Lịch sử đánh giá'!$H:$H,MATCH(2,1/('🗂️ Lịch sử đánh giá'!$A:$A=$A4))),"chưa đánh giá")} -> chưa đánh giá
A5: TTX002 | B5: Nguyễn Hoàn Vũ | C5: FALSE | F5: Tổng Giám đốc | G5: CEO - Chief Executive Officer | H5: C Suite Level (C-Level) | I5: Người nói | J5: Văn phòng | K5: C-Level | L5: =COUNTIF('🗂️ Lịch sử đánh giá'!$A:$A,$A5) -> 0 | M5: {=IFERROR(INDEX('🗂️ Lịch sử đánh giá'!$C:$C,MATCH(2,1/('🗂️ Lịch sử đánh giá'!$A:$A=$A5))),"")} | N5: {=IFERROR("CM "&INDEX('🗂️ Lịch sử đánh giá'!$F:$F,MATCH(2,1/('🗂️ Lịch sử đánh giá'!$A:$A=$A5)))&" · QL "&INDEX('🗂️ Lịch sử đánh giá'!$G:$G,MATCH(2,1/('🗂️ Lịch sử đánh giá'!$A:$A=$A5)))&" · CLV "&INDEX('🗂️ Lịch sử đánh giá'!$H:$H,MATCH(2,1/('🗂️ Lịch sử đánh giá'!$A:$A=$A5))),"chưa đánh giá")} -> chưa đánh giá
A6: TTX005 | B6: Trần Thị Thanh Hải | C6: FALSE | F6: Trưởng phòng Kế toán | G6: Head of Accounting | H6: Kế toán | I6: Người nói | J6: Làm từ xa | K6: Trưởng phòng | L6: =COUNTIF('🗂️ Lịch sử đánh giá'!$A:$A,$A6) -> 0 | M6: {=IFERROR(INDEX('🗂️ Lịch sử đánh giá'!$C:$C,MATCH(2,1/('🗂️ Lịch sử đánh giá'!$A:$A=$A6))),"")} | N6: {=IFERROR("CM "&INDEX('🗂️ Lịch sử đánh giá'!$F:$F,MATCH(2,1/('🗂️ Lịch sử đánh giá'!$A:$A=$A6)))&" · QL "&INDEX('🗂️ Lịch sử đánh giá'!$G:$G,MATCH(2,1/('🗂️ Lịch sử đánh giá'!$A:$A=$A6)))&" · CLV "&INDEX('🗂️ Lịch sử đánh giá'!$H:$H,MATCH(2,1/('🗂️ Lịch sử đánh giá'!$A:$A=$A6))),"chưa đánh giá")} -> chưa đánh giá
A7: TTX003 | B7: Nguyễn Trọng Duy | C7: FALSE | F7: Trưởng phòng Thương mại & Dịch vụ | G7: Head of Commercial & Services | H7: Thương mại & Dịch vụ | I7: Người nói | J7: Văn phòng | K7: Trưởng phòng | L7: =COUNTIF('🗂️ Lịch sử đánh giá'!$A:$A,$A7) -> 0 | M7: {=IFERROR(INDEX('🗂️ Lịch sử đánh giá'!$C:$C,MATCH(2,1/('🗂️ Lịch sử đánh giá'!$A:$A=$A7))),"")} | N7: {=IFERROR("CM "&INDEX('🗂️ Lịch sử đánh giá'!$F:$F,MATCH(2,1/('🗂️ Lịch sử đánh giá'!$A:$A=$A7)))&" · QL "&INDEX('🗂️ Lịch sử đánh giá'!$G:$G,MATCH(2,1/('🗂️ Lịch sử đánh giá'!$A:$A=$A7)))&" · CLV "&INDEX('🗂️ Lịch sử đánh giá'!$H:$H,MATCH(2,1/('🗂️ Lịch sử đánh giá'!$A:$A=$A7))),"chưa đánh giá")} -> chưa đánh giá
A8: TTX004 | B8: Trần Ngọc Phương | C8: FALSE | F8: Quản lý Sản xuất | G8: Production Manager | H8: Sản xuất | I8: Người nói | J8: Xưởng sản xuất | K8: Trưởng phòng | L8: =COUNTIF('🗂️ Lịch sử đánh giá'!$A:$A,$A8) -> 0 | M8: {=IFERROR(INDEX('🗂️ Lịch sử đánh giá'!$C:$C,MATCH(2,1/('🗂️ Lịch sử đánh giá'!$A:$A=$A8))),"")} | N8: {=IFERROR("CM "&INDEX('🗂️ Lịch sử đánh giá'!$F:$F,MATCH(2,1/('🗂️ Lịch sử đánh giá'!$A:$A=$A8)))&" · QL "&INDEX('🗂️ Lịch sử đánh giá'!$G:$G,MATCH(2,1/('🗂️ Lịch sử đánh giá'!$A:$A=$A8)))&" · CLV "&INDEX('🗂️ Lịch sử đánh giá'!$H:$H,MATCH(2,1/('🗂️ Lịch sử đánh giá'!$A:$A=$A8))),"chưa đánh giá")} -> chưa đánh giá
A9: TTX029 | B9: Hồ Đăng Phong | C9: FALSE | F9: Trưởng phòng Phát triển Phần mềm & Tự động hóa | G9: Head of Software Development & Automation | H9: Phát triển Phần mềm & Tự động hóa | I9: Người nói | J9: Văn phòng | K9: Trưởng phòng | L9: =COUNTIF('🗂️ Lịch sử đánh giá'!$A:$A,$A9) -> 1 | M9: {=IFERROR(INDEX('🗂️ Lịch sử đánh giá'!$C:$C,MATCH(2,1/('🗂️ Lịch sử đánh giá'!$A:$A=$A9))),"")} -> 2026-Q3 | N9: {=IFERROR("CM "&INDEX('🗂️ Lịch sử đánh giá'!$F:$F,MATCH(2,1/('🗂️ Lịch sử đánh giá'!$A:$A=$A9)))&" · QL "&INDEX('🗂️ Lịch sử đánh giá'!$G:$G,MATCH(2,1/('🗂️ Lịch sử đánh giá'!$A:$A=$A9)))&" · CLV "&INDEX('🗂️ Lịch sử đánh giá'!$H:$H,MATCH(2,1/('🗂️ Lịch sử đánh giá'!$A:$A=$A9))),"chưa đánh giá")} -> CM · QL · CLV
A10: TTX030 | B10: Đoàn Anh Trung | C10: FALSE | F10: Trưởng phòng Nhân sự - Hành chính - Pháp chế | G10: Head of People & Culture - Administration - Legal | H10: Nhân sự - Hành chính - Pháp chế | I10: Người nói | J10: Văn phòng | K10: Trưởng phòng | L10: =COUNTIF('🗂️ Lịch sử đánh giá'!$A:$A,$A10) -> 0 | M10: {=IFERROR(INDEX('🗂️ Lịch sử đánh giá'!$C:$C,MATCH(2,1/('🗂️ Lịch sử đánh giá'!$A:$A=$A10))),"")} | N10: {=IFERROR("CM "&INDEX('🗂️ Lịch sử đánh giá'!$F:$F,MATCH(2,1/('🗂️ Lịch sử đánh giá'!$A:$A=$A10)))&" · QL "&INDEX('🗂️ Lịch sử đánh giá'!$G:$G,MATCH(2,1/('🗂️ Lịch sử đánh giá'!$A:$A=$A10)))&" · CLV "&INDEX('🗂️ Lịch sử đánh giá'!$H:$H,MATCH(2,1/('🗂️ Lịch sử đánh giá'!$A:$A=$A10))),"chưa đánh giá")} -> chưa đánh giá
A11: TTX019 | B11: Ngô Thị Thúy Lộc | C11: FALSE | F11: Kế toán chức năng | G11: Functional Accountant | H11: Kế toán chức năng & Thuế | I11: Người nói | J11: Làm từ xa | K11: Nhân viên | L11: =COUNTIF('🗂️ Lịch sử đánh giá'!$A:$A,$A11) -> 0 | M11: {=IFERROR(INDEX('🗂️ Lịch sử đánh giá'!$C:$C,MATCH(2,1/('🗂️ Lịch sử đánh giá'!$A:$A=$A11))),"")} | N11: {=IFERROR("CM "&INDEX('🗂️ Lịch sử đánh giá'!$F:$F,MATCH(2,1/('🗂️ Lịch sử đánh giá'!$A:$A=$A11)))&" · QL "&INDEX('🗂️ Lịch sử đánh giá'!$G:$G,MATCH(2,1/('🗂️ Lịch sử đánh giá'!$A:$A=$A11)))&" · CLV "&INDEX('🗂️ Lịch sử đánh giá'!$H:$H,MATCH(2,1/('🗂️ Lịch sử đánh giá'!$A:$A=$A11))),"chưa đánh giá")} -> chưa đánh giá
A12: TTX021 | B12: Nguyễn Thị Thư | C12: FALSE | F12: Kế toán chức năng | G12: Functional Accountant | H12: Kế toán chức năng & Thuế | I12: Người nói | J12: Làm từ xa | K12: Nhân viên | L12: =COUNTIF('🗂️ Lịch sử đánh giá'!$A:$A,$A12) -> 0 | M12: {=IFERROR(INDEX('🗂️ Lịch sử đánh giá'!$C:$C,MATCH(2,1/('🗂️ Lịch sử đánh giá'!$A:$A=$A12))),"")} | N12: {=IFERROR("CM "&INDEX('🗂️ Lịch sử đánh giá'!$F:$F,MATCH(2,1/('🗂️ Lịch sử đánh giá'!$A:$A=$A12)))&" · QL "&INDEX('🗂️ Lịch sử đánh giá'!$G:$G,MATCH(2,1/('🗂️ Lịch sử đánh giá'!$A:$A=$A12)))&" · CLV "&INDEX('🗂️ Lịch sử đánh giá'!$H:$H,MATCH(2,1/('🗂️ Lịch sử đánh giá'!$A:$A=$A12))),"chưa đánh giá")} -> chưa đánh giá
A13: TTX020 | B13: Nguyễn Hoàng Thủy Nguyên | C13: FALSE | F13: Kế toán chức năng | G13: Functional Accountant | H13: Kế toán chức năng & Thuế | I13: Người nói | J13: Làm từ xa | K13: Nhân viên | L13: =COUNTIF('🗂️ Lịch sử đánh giá'!$A:$A,$A13) -> 0 | M13: {=IFERROR(INDEX('🗂️ Lịch sử đánh giá'!$C:$C,MATCH(2,1/('🗂️ Lịch sử đánh giá'!$A:$A=$A13))),"")} | N13: {=IFERROR("CM "&INDEX('🗂️ Lịch sử đánh giá'!$F:$F,MATCH(2,1/('🗂️ Lịch sử đánh giá'!$A:$A=$A13)))&" · QL "&INDEX('🗂️ Lịch sử đánh giá'!$G:$G,MATCH(2,1/('🗂️ Lịch sử đánh giá'!$A:$A=$A13)))&" · CLV "&INDEX('🗂️ Lịch sử đánh giá'!$H:$H,MATCH(2,1/('🗂️ Lịch sử đánh giá'!$A:$A=$A13))),"chưa đánh giá")} -> chưa đánh giá
A14: TTX023 | B14: Nguyễn Lê Phương Uyên | C14: FALSE | F14: Nhân viên Thương mại điện tử | G14: E-commerce Staff | H14: Thương mại & Dịch vụ | I14: Người nói | J14: Văn phòng | K14: Nhân viên | L14: =COUNTIF('🗂️ Lịch sử đánh giá'!$A:$A,$A14) -> 0 | M14: {=IFERROR(INDEX('🗂️ Lịch sử đánh giá'!$C:$C,MATCH(2,1/('🗂️ Lịch sử đánh giá'!$A:$A=$A14))),"")} | N14: {=IFERROR("CM "&INDEX('🗂️ Lịch sử đánh giá'!$F:$F,MATCH(2,1/('🗂️ Lịch sử đánh giá'!$A:$A=$A14)))&" · QL "&INDEX('🗂️ Lịch sử đánh giá'!$G:$G,MATCH(2,1/('🗂️ Lịch sử đánh giá'!$A:$A=$A14)))&" · CLV "&INDEX('🗂️ Lịch sử đánh giá'!$H:$H,MATCH(2,1/('🗂️ Lịch sử đánh giá'!$A:$A=$A14))),"chưa đánh giá")} -> chưa đánh giá
A15: TTX007 | B15: A Mỹ Ngọc | C15: FALSE | F15: Nhân viên CSKH online | G15: Online Customer Service | H15: Thương mại & Dịch vụ | I15: Người nói | J15: Làm từ xa | K15: Nhân viên | L15: =COUNTIF('🗂️ Lịch sử đánh giá'!$A:$A,$A15) -> 0 | M15: {=IFERROR(INDEX('🗂️ Lịch sử đánh giá'!$C:$C,MATCH(2,1/('🗂️ Lịch sử đánh giá'!$A:$A=$A15))),"")} | N15: {=IFERROR("CM "&INDEX('🗂️ Lịch sử đánh giá'!$F:$F,MATCH(2,1/('🗂️ Lịch sử đánh giá'!$A:$A=$A15)))&" · QL "&INDEX('🗂️ Lịch sử đánh giá'!$G:$G,MATCH(2,1/('🗂️ Lịch sử đánh giá'!$A:$A=$A15)))&" · CLV "&INDEX('🗂️ Lịch sử đánh giá'!$H:$H,MATCH(2,1/('🗂️ Lịch sử đánh giá'!$A:$A=$A15))),"chưa đánh giá")} -> chưa đánh giá
... A33: TTX018 | B33: Nguyễn Thị Thùy | C33: FALSE | F33: Nhân viên Kho & Đóng gói | G33: Warehouse & Packaging Staff | H33: Kho & Đóng gói | I33: Người nói | J33: Kho & Đóng gói | K33: Nhân viên | L33: =COUNTIF('🗂️ Lịch sử đánh giá'!$A:$A,$A33) -> 0 | M33: {=IFERROR(INDEX('🗂️ Lịch sử đánh giá'!$C:$C,MATCH(2,1/('🗂️ Lịch sử đánh giá'!$A:$A=$A33))),"")} | N33: {=IFERROR("CM "&INDEX('🗂️ Lịch sử đánh giá'!$F:$F,MATCH(2,1/('🗂️ Lịch sử đánh giá'!$A:$A=$A33)))&" · QL "&INDEX('🗂️ Lịch sử đánh giá'!$G:$G,MATCH(2,1/('🗂️ Lịch sử đánh giá'!$A:$A=$A33)))&" · CLV "&INDEX('🗂️ Lịch sử đánh giá'!$H:$H,MATCH(2,1/('🗂️ Lịch sử đánh giá'!$A:$A=$A33))),"chưa đánh giá")} -> chưa đánh giá

Sheet ⚙️ Tham số
A1: ⚙️ THAM SỐ - Sửa ở đây, mọi phiếu tính lại theo. Không bao giờ sửa số trực tiếp trong công thức.
A2: Nhóm | B2: Tham số | C2: Giá trị | D2: Đơn vị | E2: Giải thích | F2: Bậc
A3: I. GHÉP RA BẬC TRONG NGẠCH
B4: Ngưỡng đa số tiêu chí | C4: 0.6 | D4: tỷ lệ | E4: Chỉ dùng cho tuyến KHÔNG có thang cộng dồn. Người đó được coi là ở bậc b khi đạt bậc b ở ít nhất tỷ lệ này của số tiêu chí trong phạm vi. ⚠️ Chưa được chốt.
B5: Mức tụt tối đa cho phép | C5: 1 | D5: nấc | E5: ⛔ KHÔNG CÒN CHỖ DÙNG từ 31/8/2026. Hai dòng bậc trong ngạch đã bỏ khỏi phiếu, nên tham số này không đi vào công thức nào nữa. Giữ lại chờ Ban lãnh đạo quyết bỏ hay giữ.
B6: Ngưỡng đạt của một dải cấp | C6: 0.8 | D6: tỷ lệ đạt | E6: ⛔ KHÔNG CÒN CHỖ DÙNG từ 31/8/2026, cùng lý do dòng trên.
A7: II. GHÉP RA BẬC CÁCH LÀM VIỆC
B8: Ngưỡng ra bậc 1 | C8: 0 | D8: tỷ lệ đạt | E8: Tỷ lệ đạt của phần cách làm việc, quy ra bậc. ⚠️ Chưa hiệu chỉnh bằng dữ liệu thật. | F8: 1
B9: Ngưỡng ra bậc 2 | C9: 0.4 | D9: tỷ lệ đạt | F9: 2
B10: Ngưỡng ra bậc 3 | C10: 0.55 | D10: tỷ lệ đạt | F10: 3
B11: Ngưỡng ra bậc 4 | C11: 0.7 | D11: tỷ lệ đạt | F11: 4
B12: Ngưỡng ra bậc 5 | C12: 0.85 | D12: tỷ lệ đạt | F12: 5
A13: III. TRỌNG SỐ GHÉP RA ĐIỂM TỔNG THÁNG
B14: Văn hóa chung, khi KHÔNG có ngạch quản lý | C14: 0.65 | D14: trọng số | E14: Áp cho nhân sự chỉ chấm hai phần là văn hóa chung và ngạch chuyên môn. Cặp này phải cộng lại bằng 100%.
B15: Ngạch chuyên môn, khi KHÔNG có ngạch quản lý | C15: 0.35 | D15: trọng số
B16: Văn hóa chung, khi CÓ ngạch quản lý | C16: 0.5 | D16: trọng số | E16: Áp cho nhân sự chấm cả ba phần. Bộ ba này phải cộng lại bằng 100%.
B17: Ngạch quản lý, khi CÓ ngạch quản lý | C17: 0.3 | D17: trọng số
B18: Ngạch chuyên môn, khi CÓ ngạch quản lý | C18: 0.2 | D18: trọng số
A19: IV. NỐI VỚI DRIVE VÀ VỚI FILE PEOPLE MANAGEMENT
B20: ID thư mục chứa các đợt | D20: ID Drive | E20: ĐỂ TRỐNG là đúng trong hầu hết trường hợp: hệ tự dùng chính thư mục đang chứa file gốc này, nên cây đánh giá luôn nằm trong thư mục People cùng chỗ với file gốc. Chỉ dán ID vào đây khi muốn đặt các đợt ở một thư mục khác.
B21: ID file People Management | C21: 1Ruf3EeXiaiV0Jifnewe-HefXW4ncZHJvlItuoti4vus | D21: ID Drive | E21: Nguồn danh sách nhân sự. Menu 🔃 Đồng bộ nhân sự đọc sheet "👥 Nhân sự" của file này. Danh sách nhân sự KHÔNG nhập tay ở đây, để tránh hai nơi cùng giữ một dữ liệu rồi trôi lệch.
A22: V. NGUYÊN TẮC CỐ ĐỊNH, KHÔNG PHẢI THAM SỐ
B23: Điểm mặc định đầu tháng, nhóm đo VI PHẠM | C23: 5 | D23: điểm | E23: Đầu tháng chưa có biên bản nào thì câu ở nhóm đo vi phạm đứng ở 5, tức chưa vi phạm lần nào. Mỗi biên bản vi phạm kéo điểm xuống.
B24: Điểm mặc định đầu tháng, nhóm đo GHI NHẬN | C24: 0 | D24: điểm | E24: Đầu tháng chưa có phiếu nào thì câu ở nhóm đo ghi nhận đứng ở 0, tức chưa ghi nhận lần nào. Mỗi phiếu ghi nhận đẩy điểm lên.
B25: Phiếu tự xếp CẤP cho nhân sự | C25: Không | E25: ✅ CHỐT 31/8/2026 (Sen). Cấp, tức Chuyên viên, Lead bộ phận, Trưởng phòng, đi qua quyết định bổ nhiệm chứ không do một phiếu tháng quyết. Phiếu chỉ cho ra BẬC CÁCH LÀM VIỆC.
B26: Vi phạm nội quy trừ thẳng ra bậc và ra tiền | C26: Không, trừ một ngoại lệ | E26: Pháp luật lao động nghiêm cấm phạt tiền và cắt lương thay cho xử lý kỷ luật. Vi phạm là MỘT TRONG NHIỀU căn cứ khi chấm trụ văn hóa, không có công thức tự trừ. Muốn xử nặng thì đi đường kỷ luật lao động, trong đó có hình thức kéo dài thời hạn nâng bậc tối đa 6 tháng. NGOẠI LỆ DUY NHẤT, ✅ CHỐT 11/8/2026 (Sen): vi phạm bảo mật thu nhập cá nhân, mục VII của phiếu, trừ thẳng 1 bậc của Bậc cách làm việc, sàn là bậc 1. Chỉ trừ vào bậc đó, không đụng tới CẤP của người đó. ⚠️ Điều kiện để dùng làm căn cứ: nghĩa vụ bảo mật thu nhập phải nằm trong hợp đồng lao động hoặc nội quy lao động đã ban hành.
B27: Tiêu chí ngoài phạm vi tính là chưa đạt | C27: Không | E27: Đặt cột Thuộc phạm vi bằng Không thì ô đó rời khỏi cả tử số lẫn mẫu số.
B28: Phiếu tự quy kết quả ra số tiền | C28: Không | E28: Phiếu dừng ở bậc cách làm việc. Ban lãnh đạo nhìn hai thang chuyên môn và quản lý để quyết bổ nhiệm chức danh; chức danh nào ứng với số tiền nào do quy chế lương quy định.

Sheet 📚 Bộ câu hỏi
A1: 📚 BỘ CÂU HỎI ĐÁNH GIÁ - NGUỒN DUY NHẤT của bộ câu hỏi. Dòng nền xanh đậm là một PHẦN, dòng nền xanh nhạt là một NHÓM, dòng trắng là một CÂU. Cột A bật tắt đúng thứ nằm trên dòng đó. Điểm nền xem sheet 📊 Điểm nền.
A2: Kích hoạt | B2: Phần | C2: Tuyến | D2: Mã nhóm | E2: Tên nhóm | F2: Chiều đo | G2: Mã câu | H2: Câu hỏi | I2: Phạm vi áp dụng | J2: Ghi chú | K2: Vào phiếu | L2: Khóa
A3: Có | B3: Chung | K3: {=IF($B3="","",IF($A3<>"Có","Không",IF($G3="","Có",IF(IFERROR(INDEX('📚 Bộ câu hỏi'!$A$3:$A1059,MATCH($B3&"|"&$C3&"|",'📚 Bộ câu hỏi'!$L$3:$L1059,0)),"Có")="Không","Không",IF(IFERROR(INDEX('📚 Bộ câu hỏi'!$A$3:$A1059,MATCH($B3&"|"&$C3&"|"&$D3,'📚 Bộ câu hỏi'!$L$3:$L1059,0)),"Có")="Không","Không","Có")))))} -> Có | L3: =IF($B3="","",$B3&"|"&$C3&"|"&$D3) -> Chung||
A4: Có | B4: Chung | D4: VH1 | E4: ONE VOICE, MỘT TIẾNG NÓI THỐNG NHẤT | F4: vi phạm | K4: {=IF($B4="","",IF($A4<>"Có","Không",IF($G4="","Có",IF(IFERROR(INDEX('📚 Bộ câu hỏi'!$A$3:$A1059,MATCH($B4&"|"&$C4&"|",'📚 Bộ câu hỏi'!$L$3:$L1059,0)),"Có")="Không","Không",IF(IFERROR(INDEX('📚 Bộ câu hỏi'!$A$3:$A1059,MATCH($B4&"|"&$C4&"|"&$D4,'📚 Bộ câu hỏi'!$L$3:$L1059,0)),"Có")="Không","Không","Có")))))} -> Có | L4: =IF($B4="","",$B4&"|"&$C4&"|"&$D4) -> Chung||VH1
A5: Có | B5: Chung | D5: VH1 | E5: ONE VOICE, MỘT TIẾNG NÓI THỐNG NHẤT | F5: vi phạm | G5: VH1.1 | H5: Nhân sự có phát ngôn cá nhân trái định hướng chung của Công ty | I5: Tất cả nhân sự | K5: {=IF($B5="","",IF($A5<>"Có","Không",IF($G5="","Có",IF(IFERROR(INDEX('📚 Bộ câu hỏi'!$A$3:$A1059,MATCH($B5&"|"&$C5&"|",'📚 Bộ câu hỏi'!$L$3:$L1059,0)),"Có")="Không","Không",IF(IFERROR(INDEX('📚 Bộ câu hỏi'!$A$3:$A1059,MATCH($B5&"|"&$C5&"|"&$D5,'📚 Bộ câu hỏi'!$L$3:$L1059,0)),"Có")="Không","Không","Có")))))} -> Có | L5: =IF($B5="","",$B5&"|"&$C5&"|"&$D5) -> Chung||VH1
A6: Có | B6: Chung | D6: VH1 | E6: ONE VOICE, MỘT TIẾNG NÓI THỐNG NHẤT | F6: vi phạm | G6: VH1.2 | H6: Nhân sự truyền đạt thông tin chưa được xác nhận | I6: Tất cả nhân sự | K6: {=IF($B6="","",IF($A6<>"Có","Không",IF($G6="","Có",IF(IFERROR(INDEX('📚 Bộ câu hỏi'!$A$3:$A1059,MATCH($B6&"|"&$C6&"|",'📚 Bộ câu hỏi'!$L$3:$L1059,0)),"Có")="Không","Không",IF(IFERROR(INDEX('📚 Bộ câu hỏi'!$A$3:$A1059,MATCH($B6&"|"&$C6&"|"&$D6,'📚 Bộ câu hỏi'!$L$3:$L1059,0)),"Có")="Không","Không","Có")))))} -> Có | L6: =IF($B6="","",$B6&"|"&$C6&"|"&$D6) -> Chung||VH1
A7: Có | B7: Chung | D7: VH1 | E7: ONE VOICE, MỘT TIẾNG NÓI THỐNG NHẤT | F7: vi phạm | G7: VH1.3 | H7: Nhân sự dùng sai hoặc bỏ qua kịch bản và quy chuẩn giao tiếp đã ban hành, cả với khách và trong nội bộ | I7: Tất cả nhân sự | K7: {=IF($B7="","",IF($A7<>"Có","Không",IF($G7="","Có",IF(IFERROR(INDEX('📚 Bộ câu hỏi'!$A$3:$A1059,MATCH($B7&"|"&$C7&"|",'📚 Bộ câu hỏi'!$L$3:$L1059,0)),"Có")="Không","Không",IF(IFERROR(INDEX('📚 Bộ câu hỏi'!$A$3:$A1059,MATCH($B7&"|"&$C7&"|"&$D7,'📚 Bộ câu hỏi'!$L$3:$L1059,0)),"Có")="Không","Không","Có")))))} -> Có | L7: =IF($B7="","",$B7&"|"&$C7&"|"&$D7) -> Chung||VH1
A8: Có | B8: Chung | D8: VH1 | E8: ONE VOICE, MỘT TIẾNG NÓI THỐNG NHẤT | F8: vi phạm | G8: VH1.4 | H8: Nhân sự tự ý trả lời khách hoặc đồng nghiệp thông tin chưa chắc chắn thay vì xác nhận lại với người có thẩm quyền | I8: Tất cả nhân sự | K8: {=IF($B8="","",IF($A8<>"Có","Không",IF($G8="","Có",IF(IFERROR(INDEX('📚 Bộ câu hỏi'!$A$3:$A1059,MATCH($B8&"|"&$C8&"|",'📚 Bộ câu hỏi'!$L$3:$L1059,0)),"Có")="Không","Không",IF(IFERROR(INDEX('📚 Bộ câu hỏi'!$A$3:$A1059,MATCH($B8&"|"&$C8&"|"&$D8,'📚 Bộ câu hỏi'!$L$3:$L1059,0)),"Có")="Không","Không","Có")))))} -> Có | L8: =IF($B8="","",$B8&"|"&$C8&"|"&$D8) -> Chung||VH1
A9: Có | B9: Chung | D9: VH1 | E9: ONE VOICE, MỘT TIẾNG NÓI THỐNG NHẤT | F9: vi phạm | G9: VH1.5 | H9: Nhân sự truyền đạt chính sách hoặc quyết định sai lệch, thiếu sót nội dung so với văn bản gốc đã ban hành | I9: Tất cả nhân sự | K9: {=IF($B9="","",IF($A9<>"Có","Không",IF($G9="","Có",IF(IFERROR(INDEX('📚 Bộ câu hỏi'!$A$3:$A1059,MATCH($B9&"|"&$C9&"|",'📚 Bộ câu hỏi'!$L$3:$L1059,0)),"Có")="Không","Không",IF(IFERROR(INDEX('📚 Bộ câu hỏi'!$A$3:$A1059,MATCH($B9&"|"&$C9&"|"&$D9,'📚 Bộ câu hỏi'!$L$3:$L1059,0)),"Có")="Không","Không","Có")))))} -> Có | L9: =IF($B9="","",$B9&"|"&$C9&"|"&$D9) -> Chung||VH1
A10: Có | B10: Chung | D10: VH2 | E10: OUTCOME, KẾT QUẢ CẦN ĐẠT THEO TIÊU CHÍ SMART | F10: vi phạm | K10: {=IF($B10="","",IF($A10<>"Có","Không",IF($G10="","Có",IF(IFERROR(INDEX('📚 Bộ câu hỏi'!$A$3:$A1059,MATCH($B10&"|"&$C10&"|",'📚 Bộ câu hỏi'!$L$3:$L1059,0)),"Có")="Không","Không",IF(IFERROR(INDEX('📚 Bộ câu hỏi'!$A$3:$A1059,MATCH($B10&"|"&$C10&"|"&$D10,'📚 Bộ câu hỏi'!$L$3:$L1059,0)),"Có")="Không","Không","Có")))))} -> Có | L10: =IF($B10="","",$B10&"|"&$C10&"|"&$D10) -> Chung||VH2
A11: Có | B11: Chung | D11: VH2 | E11: OUTCOME, KẾT QUẢ CẦN ĐẠT THEO TIÊU CHÍ SMART | F11: vi phạm | G11: VH2.1 | H11: Nhân sự nhận việc mà không nêu được kết quả cần đạt, chỉ mô tả các hoạt động sẽ làm | I11: Tất cả nhân sự | K11: {=IF($B11="","",IF($A11<>"Có","Không",IF($G11="","Có",IF(IFERROR(INDEX('📚 Bộ câu hỏi'!$A$3:$A1059,MATCH($B11&"|"&$C11&"|",'📚 Bộ câu hỏi'!$L$3:$L1059,0)),"Có")="Không","Không",IF(IFERROR(INDEX('📚 Bộ câu hỏi'!$A$3:$A1059,MATCH($B11&"|"&$C11&"|"&$D11,'📚 Bộ câu hỏi'!$L$3:$L1059,0)),"Có")="Không","Không","Có")))))} -> Có | L11: =IF($B11="","",$B11&"|"&$C11&"|"&$D11) -> Chung||VH2
A12: Có | B12: Chung | D12: VH2 | E12: OUTCOME, KẾT QUẢ CẦN ĐẠT THEO TIÊU CHÍ SMART | F12: vi phạm | G12: VH2.2 | H12: Kết quả cần đạt do nhân sự nêu không đo được bằng số hoặc bằng dữ kiện kiểm chứng được | I12: Tất cả nhân sự | K12: {=IF($B12="","",IF($A12<>"Có","Không",IF($G12="","Có",IF(IFERROR(INDEX('📚 Bộ câu hỏi'!$A$3:$A1059,MATCH($B12&"|"&$C12&"|",'📚 Bộ câu hỏi'!$L$3:$L1059,0)),"Có")="Không","Không",IF(IFERROR(INDEX('📚 Bộ câu hỏi'!$A$3:$A1059,MATCH($B12&"|"&$C12&"|"&$D12,'📚 Bộ câu hỏi'!$L$3:$L1059,0)),"Có")="Không","Không","Có")))))} -> Có | L12: =IF($B12="","",$B12&"|"&$C12&"|"&$D12) -> Chung||VH2
A13: Có | B13: Chung | D13: VH2 | E13: OUTCOME, KẾT QUẢ CẦN ĐẠT THEO TIÊU CHÍ SMART | F13: vi phạm | G13: VH2.3 | H13: Kết quả cần đạt do nhân sự nêu không khả thi với nguồn lực và thời gian đang có | I13: Tất cả nhân sự | K13: {=IF($B13="","",IF($A13<>"Có","Không",IF($G13="","Có",IF(IFERROR(INDEX('📚 Bộ câu hỏi'!$A$3:$A1059,MATCH($B13&"|"&$C13&"|",'📚 Bộ câu hỏi'!$L$3:$L1059,0)),"Có")="Không","Không",IF(IFERROR(INDEX('📚 Bộ câu hỏi'!$A$3:$A1059,MATCH($B13&"|"&$C13&"|"&$D13,'📚 Bộ câu hỏi'!$L$3:$L1059,0)),"Có")="Không","Không","Có")))))} -> Có | L13: =IF($B13="","",$B13&"|"&$C13&"|"&$D13) -> Chung||VH2
A14: Có | B14: Chung | D14: VH2 | E14: OUTCOME, KẾT QUẢ CẦN ĐẠT THEO TIÊU CHÍ SMART | F14: vi phạm | G14: VH2.4 | H14: Kết quả cần đạt do nhân sự nêu không phục vụ đúng mục tiêu của bộ phận | I14: Tất cả nhân sự | K14: {=IF($B14="","",IF($A14<>"Có","Không",IF($G14="","Có",IF(IFERROR(INDEX('📚 Bộ câu hỏi'!$A$3:$A1059,MATCH($B14&"|"&$C14&"|",'📚 Bộ câu hỏi'!$L$3:$L1059,0)),"Có")="Không","Không",IF(IFERROR(INDEX('📚 Bộ câu hỏi'!$A$3:$A1059,MATCH($B14&"|"&$C14&"|"&$D14,'📚 Bộ câu hỏi'!$L$3:$L1059,0)),"Có")="Không","Không","Có")))))} -> Có | L14: =IF($B14="","",$B14&"|"&$C14&"|"&$D14) -> Chung||VH2
A15: Có | B15: Chung | D15: VH2 | E15: OUTCOME, KẾT QUẢ CẦN ĐẠT THEO TIÊU CHÍ SMART | F15: vi phạm | G15: VH2.5 | H15: Kết quả cần đạt do nhân sự nêu không có thời hạn rõ ràng | I15: Tất cả nhân sự | K15: {=IF($B15="","",IF($A15<>"Có","Không",IF($G15="","Có",IF(IFERROR(INDEX('📚 Bộ câu hỏi'!$A$3:$A1059,MATCH($B15&"|"&$C15&"|",'📚 Bộ câu hỏi'!$L$3:$L1059,0)),"Có")="Không","Không",IF(IFERROR(INDEX('📚 Bộ câu hỏi'!$A$3:$A1059,MATCH($B15&"|"&$C15&"|"&$D15,'📚 Bộ câu hỏi'!$L$3:$L1059,0)),"Có")="Không","Không","Có")))))} -> Có | L15: =IF($B15="","",$B15&"|"&$C15&"|"&$D15) -> Chung||VH2
A16: Có | B16: Chung | D16: VH2 | E16: OUTCOME, KẾT QUẢ CẦN ĐẠT THEO TIÊU CHÍ SMART | F16: vi phạm | G16: VH2.6 | H16: Nhân sự không chủ động báo cáo nghiệm thu kết quả công việc bằng số liệu hoặc dữ kiện thực tế khi đến hạn | I16: Tất cả nhân sự | K16: {=IF($B16="","",IF($A16<>"Có","Không",IF($G16="","Có",IF(IFERROR(INDEX('📚 Bộ câu hỏi'!$A$3:$A1059,MATCH($B16&"|"&$C16&"|",'📚 Bộ câu hỏi'!$L$3:$L1059,0)),"Có")="Không","Không",IF(IFERROR(INDEX('📚 Bộ câu hỏi'!$A$3:$A1059,MATCH($B16&"|"&$C16&"|"&$D16,'📚 Bộ câu hỏi'!$L$3:$L1059,0)),"Có")="Không","Không","Có")))))} -> Có | L16: =IF($B16="","",$B16&"|"&$C16&"|"&$D16) -> Chung||VH2
A17: Có | B17: Chung | D17: VH2 | E17: OUTCOME, KẾT QUẢ CẦN ĐẠT THEO TIÊU CHÍ SMART | F17: vi phạm | G17: VH2.7 | H17: Kết quả cần đạt nhân sự giao cho nhóm bị hiểu theo nhiều cách, tới lúc nghiệm thu mới phát sinh tranh cãi | I17: Nhân sự giữ vai trò quản lý | K17: {=IF($B17="","",IF($A17<>"Có","Không",IF($G17="","Có",IF(IFERROR(INDEX('📚 Bộ câu hỏi'!$A$3:$A1059,MATCH($B17&"|"&$C17&"|",'📚 Bộ câu hỏi'!$L$3:$L1059,0)),"Có")="Không","Không",IF(IFERROR(INDEX('📚 Bộ câu hỏi'!$A$3:$A1059,MATCH($B17&"|"&$C17&"|"&$D17,'📚 Bộ câu hỏi'!$L$3:$L1059,0)),"Có")="Không","Không","Có")))))} -> Có | L17: =IF($B17="","",$B17&"|"&$C17&"|"&$D17) -> Chung||VH2
A18: Có | B18: Chung | D18: VH3 | E18: PURPOSE, MỤC ĐÍCH VÀ VÌ SAO LÀM | F18: vi phạm | K18: {=IF($B18="","",IF($A18<>"Có","Không",IF($G18="","Có",IF(IFERROR(INDEX('📚 Bộ câu hỏi'!$A$3:$A1059,MATCH($B18&"|"&$C18&"|",'📚 Bộ câu hỏi'!$L$3:$L1059,0)),"Có")="Không","Không",IF(IFERROR(INDEX('📚 Bộ câu hỏi'!$A$3:$A1059,MATCH($B18&"|"&$C18&"|"&$D18,'📚 Bộ câu hỏi'!$L$3:$L1059,0)),"Có")="Không","Không","Có")))))} -> Có | L18: =IF($B18="","",$B18&"|"&$C18&"|"&$D18) -> Chung||VH3
A19: Có | B19: Chung | D19: VH3 | E19: PURPOSE, MỤC ĐÍCH VÀ VÌ SAO LÀM | F19: vi phạm | G19: VH3.1 | H19: Nhân sự không nhắc lại được vì sao việc mình nhận cần làm | I19: Tất cả nhân sự | K19: {=IF($B19="","",IF($A19<>"Có","Không",IF($G19="","Có",IF(IFERROR(INDEX('📚 Bộ câu hỏi'!$A$3:$A1059,MATCH($B19&"|"&$C19&"|",'📚 Bộ câu hỏi'!$L$3:$L1059,0)),"Có")="Không","Không",IF(IFERROR(INDEX('📚 Bộ câu hỏi'!$A$3:$A1059,MATCH($B19&"|"&$C19&"|"&$D19,'📚 Bộ câu hỏi'!$L$3:$L1059,0)),"Có")="Không","Không","Có")))))} -> Có | L19: =IF($B19="","",$B19&"|"&$C19&"|"&$D19) -> Chung||VH3
A20: Có | B20: Chung | D20: VH3 | E20: PURPOSE, MỤC ĐÍCH VÀ VÌ SAO LÀM | F20: vi phạm | G20: VH3.2 | H20: Nhân sự thực hiện công việc sai lệch so với mục tiêu chung của bộ phận hoặc kế hoạch ca đã giao | I20: Tất cả nhân sự | K20: {=IF($B20="","",IF($A20<>"Có","Không",IF($G20="","Có",IF(IFERROR(INDEX('📚 Bộ câu hỏi'!$A$3:$A1059,MATCH($B20&"|"&$C20&"|",'📚 Bộ câu hỏi'!$L$3:$L1059,0)),"Có")="Không","Không",IF(IFERROR(INDEX('📚 Bộ câu hỏi'!$A$3:$A1059,MATCH($B20&"|"&$C20&"|"&$D20,'📚 Bộ câu hỏi'!$L$3:$L1059,0)),"Có")="Không","Không","Có")))))} -> Có | L20: =IF($B20="","",$B20&"|"&$C20&"|"&$D20) -> Chung||VH3
A21: Có | B21: Chung | D21: VH3 | E21: PURPOSE, MỤC ĐÍCH VÀ VÌ SAO LÀM | F21: vi phạm | G21: VH3.3 | H21: Cách làm hiện tại không còn phục vụ đúng mục đích mà nhân sự không nêu lại với người phụ trách | I21: Tất cả nhân sự | K21: {=IF($B21="","",IF($A21<>"Có","Không",IF($G21="","Có",IF(IFERROR(INDEX('📚 Bộ câu hỏi'!$A$3:$A1059,MATCH($B21&"|"&$C21&"|",'📚 Bộ câu hỏi'!$L$3:$L1059,0)),"Có")="Không","Không",IF(IFERROR(INDEX('📚 Bộ câu hỏi'!$A$3:$A1059,MATCH($B21&"|"&$C21&"|"&$D21,'📚 Bộ câu hỏi'!$L$3:$L1059,0)),"Có")="Không","Không","Có")))))} -> Có | L21: =IF($B21="","",$B21&"|"&$C21&"|"&$D21) -> Chung||VH3
A22: Có | B22: Chung | D22: VH3 | E22: PURPOSE, MỤC ĐÍCH VÀ VÌ SAO LÀM | F22: vi phạm | G22: VH3.4 | H22: Nhân sự giao việc cho người khác mà chỉ nêu đầu việc, không nêu mục đích | I22: Nhân sự giữ vai trò quản lý | K22: {=IF($B22="","",IF($A22<>"Có","Không",IF($G22="","Có",IF(IFERROR(INDEX('📚 Bộ câu hỏi'!$A$3:$A1059,MATCH($B22&"|"&$C22&"|",'📚 Bộ câu hỏi'!$L$3:$L1059,0)),"Có")="Không","Không",IF(IFERROR(INDEX('📚 Bộ câu hỏi'!$A$3:$A1059,MATCH($B22&"|"&$C22&"|"&$D22,'📚 Bộ câu hỏi'!$L$3:$L1059,0)),"Có")="Không","Không","Có")))))} -> Có | L22: =IF($B22="","",$B22&"|"&$C22&"|"&$D22) -> Chung||VH3
A23: Có | B23: Chung | D23: VH3 | E23: PURPOSE, MỤC ĐÍCH VÀ VÌ SAO LÀM | F23: vi phạm | G23: VH3.5 | H23: Nhân sự tự ý thay đổi cách làm hoặc cắt giảm công đoạn, gây ảnh hưởng xấu đến trải nghiệm của khách hoặc chất lượng chung | I23: Tất cả nhân sự | K23: {=IF($B23="","",IF($A23<>"Có","Không",IF($G23="","Có",IF(IFERROR(INDEX('📚 Bộ câu hỏi'!$A$3:$A1059,MATCH($B23&"|"&$C23&"|",'📚 Bộ câu hỏi'!$L$3:$L1059,0)),"Có")="Không","Không",IF(IFERROR(INDEX('📚 Bộ câu hỏi'!$A$3:$A1059,MATCH($B23&"|"&$C23&"|"&$D23,'📚 Bộ câu hỏi'!$L$3:$L1059,0)),"Có")="Không","Không","Có")))))} -> Có | L23: =IF($B23="","",$B23&"|"&$C23&"|"&$D23) -> Chung||VH3
A24: Có | B24: Chung | D24: VH3 | E24: PURPOSE, MỤC ĐÍCH VÀ VÌ SAO LÀM | F24: vi phạm | G24: VH3.6 | H24: Nhân sự truyền đạt một chủ trương chung mà không diễn giải thành lý do cụ thể cho bộ phận mình phụ trách | I24: Nhân sự giữ vai trò quản lý | K24: {=IF($B24="","",IF($A24<>"Có","Không",IF($G24="","Có",IF(IFERROR(INDEX('📚 Bộ câu hỏi'!$A$3:$A1059,MATCH($B24&"|"&$C24&"|",'📚 Bộ câu hỏi'!$L$3:$L1059,0)),"Có")="Không","Không",IF(IFERROR(INDEX('📚 Bộ câu hỏi'!$A$3:$A1059,MATCH($B24&"|"&$C24&"|"&$D24,'📚 Bộ câu hỏi'!$L$3:$L1059,0)),"Có")="Không","Không","Có")))))} -> Có | L24: =IF($B24="","",$B24&"|"&$C24&"|"&$D24) -> Chung||VH3
A25: Có | B25: Chung | D25: VH4 | E25: ACTION PLAN, KẾ HOẠCH HÀNH ĐỘNG | F25: vi phạm | K25: {=IF($B25="","",IF($A25<>"Có","Không",IF($G25="","Có",IF(IFERROR(INDEX('📚 Bộ câu hỏi'!$A$3:$A1059,MATCH($B25&"|"&$C25&"|",'📚 Bộ câu hỏi'!$L$3:$L1059,0)),"Có")="Không","Không",IF(IFERROR(INDEX('📚 Bộ câu hỏi'!$A$3:$A1059,MATCH($B25&"|"&$C25&"|"&$D25,'📚 Bộ câu hỏi'!$L$3:$L1059,0)),"Có")="Không","Không","Có")))))} -> Có | L25: =IF($B25="","",$B25&"|"&$C25&"|"&$D25) -> Chung||VH4
A26: Có | B26: Chung | D26: VH4 | E26: ACTION PLAN, KẾ HOẠCH HÀNH ĐỘNG | F26: vi phạm | G26: VH4.1 | H26: Nhân sự bắt tay vào việc mà chưa nêu được các bước sẽ làm | I26: Tất cả nhân sự | K26: {=IF($B26="","",IF($A26<>"Có","Không",IF($G26="","Có",IF(IFERROR(INDEX('📚 Bộ câu hỏi'!$A$3:$A1059,MATCH($B26&"|"&$C26&"|",'📚 Bộ câu hỏi'!$L$3:$L1059,0)),"Có")="Không","Không",IF(IFERROR(INDEX('📚 Bộ câu hỏi'!$A$3:$A1059,MATCH($B26&"|"&$C26&"|"&$D26,'📚 Bộ câu hỏi'!$L$3:$L1059,0)),"Có")="Không","Không","Có")))))} -> Có | L26: =IF($B26="","",$B26&"|"&$C26&"|"&$D26) -> Chung||VH4
A27: Có | B27: Chung | D27: VH4 | E27: ACTION PLAN, KẾ HOẠCH HÀNH ĐỘNG | F27: vi phạm | G27: VH4.2 | H27: Kế hoạch của nhân sự là một danh sách rời, không có thời gian và thứ tự | I27: Tất cả nhân sự | K27: {=IF($B27="","",IF($A27<>"Có","Không",IF($G27="","Có",IF(IFERROR(INDEX('📚 Bộ câu hỏi'!$A$3:$A1059,MATCH($B27&"|"&$C27&"|",'📚 Bộ câu hỏi'!$L$3:$L1059,0)),"Có")="Không","Không",IF(IFERROR(INDEX('📚 Bộ câu hỏi'!$A$3:$A1059,MATCH($B27&"|"&$C27&"|"&$D27,'📚 Bộ câu hỏi'!$L$3:$L1059,0)),"Có")="Không","Không","Có")))))} -> Có | L27: =IF($B27="","",$B27&"|"&$C27&"|"&$D27) -> Chung||VH4
A28: Có | B28: Chung | D28: VH4 | E28: ACTION PLAN, KẾ HOẠCH HÀNH ĐỘNG | F28: vi phạm | G28: VH4.3 | H28: Nhân sự báo cáo bằng cách kể lại việc đã làm, không báo theo kế hoạch đã nêu | I28: Tất cả nhân sự | K28: {=IF($B28="","",IF($A28<>"Có","Không",IF($G28="","Có",IF(IFERROR(INDEX('📚 Bộ câu hỏi'!$A$3:$A1059,MATCH($B28&"|"&$C28&"|",'📚 Bộ câu hỏi'!$L$3:$L1059,0)),"Có")="Không","Không",IF(IFERROR(INDEX('📚 Bộ câu hỏi'!$A$3:$A1059,MATCH($B28&"|"&$C28&"|"&$D28,'📚 Bộ câu hỏi'!$L$3:$L1059,0)),"Có")="Không","Không","Có")))))} -> Có | L28: =IF($B28="","",$B28&"|"&$C28&"|"&$D28) -> Chung||VH4
A29: Có | B29: Chung | D29: VH4 | E29: ACTION PLAN, KẾ HOẠCH HÀNH ĐỘNG | F29: vi phạm | G29: VH4.4 | H29: Kế hoạch của nhân sự bỏ qua các rủi ro đã được cảnh báo trước, hoặc không có phương án xử lý khi phát sinh sự cố đã lường trước | I29: Tất cả nhân sự | K29: {=IF($B29="","",IF($A29<>"Có","Không",IF($G29="","Có",IF(IFERROR(INDEX('📚 Bộ câu hỏi'!$A$3:$A1059,MATCH($B29&"|"&$C29&"|",'📚 Bộ câu hỏi'!$L$3:$L1059,0)),"Có")="Không","Không",IF(IFERROR(INDEX('📚 Bộ câu hỏi'!$A$3:$A1059,MATCH($B29&"|"&$C29&"|"&$D29,'📚 Bộ câu hỏi'!$L$3:$L1059,0)),"Có")="Không","Không","Có")))))} -> Có | L29: =IF($B29="","",$B29&"|"&$C29&"|"&$D29) -> Chung||VH4
A30: Có | B30: Chung | D30: VH4 | E30: ACTION PLAN, KẾ HOẠCH HÀNH ĐỘNG | F30: vi phạm | G30: VH4.5 | H30: Kế hoạch nhân sự giao cho người khác thiếu thời gian, người phụ trách, nguồn lực hoặc mốc đánh giá | I30: Nhân sự giữ vai trò quản lý | K30: {=IF($B30="","",IF($A30<>"Có","Không",IF($G30="","Có",IF(IFERROR(INDEX('📚 Bộ câu hỏi'!$A$3:$A1059,MATCH($B30&"|"&$C30&"|",'📚 Bộ câu hỏi'!$L$3:$L1059,0)),"Có")="Không","Không",IF(IFERROR(INDEX('📚 Bộ câu hỏi'!$A$3:$A1059,MATCH($B30&"|"&$C30&"|"&$D30,'📚 Bộ câu hỏi'!$L$3:$L1059,0)),"Có")="Không","Không","Có")))))} -> Có | L30: =IF($B30="","",$B30&"|"&$C30&"|"&$D30) -> Chung||VH4
A31: Có | B31: Chung | D31: VH5 | E31: TIME MANAGEMENT, QUẢN LÝ THỜI GIAN | F31: vi phạm | K31: {=IF($B31="","",IF($A31<>"Có","Không",IF($G31="","Có",IF(IFERROR(INDEX('📚 Bộ câu hỏi'!$A$3:$A1059,MATCH($B31&"|"&$C31&"|",'📚 Bộ câu hỏi'!$L$3:$L1059,0)),"Có")="Không","Không",IF(IFERROR(INDEX('📚 Bộ câu hỏi'!$A$3:$A1059,MATCH($B31&"|"&$C31&"|"&$D31,'📚 Bộ câu hỏi'!$L$3:$L1059,0)),"Có")="Không","Không","Có")))))} -> Có | L31: =IF($B31="","",$B31&"|"&$C31&"|"&$D31) -> Chung||VH5
A32: Có | B32: Chung | D32: VH5 | E32: TIME MANAGEMENT, QUẢN LÝ THỜI GIAN | F32: vi phạm | G32: VH5.1 | H32: Nhân sự tập trung làm các công việc không quan trọng, bỏ quên công việc quan trọng hoặc khẩn cấp được giao trong ca | I32: Tất cả nhân sự | K32: {=IF($B32="","",IF($A32<>"Có","Không",IF($G32="","Có",IF(IFERROR(INDEX('📚 Bộ câu hỏi'!$A$3:$A1059,MATCH($B32&"|"&$C32&"|",'📚 Bộ câu hỏi'!$L$3:$L1059,0)),"Có")="Không","Không",IF(IFERROR(INDEX('📚 Bộ câu hỏi'!$A$3:$A1059,MATCH($B32&"|"&$C32&"|"&$D32,'📚 Bộ câu hỏi'!$L$3:$L1059,0)),"Có")="Không","Không","Có")))))} -> Có | L32: =IF($B32="","",$B32&"|"&$C32&"|"&$D32) -> Chung||VH5
A33: Có | B33: Chung | D33: VH5 | E33: TIME MANAGEMENT, QUẢN LÝ THỜI GIAN | F33: vi phạm | G33: VH5.2 | H33: Khi có nhiều việc cùng lúc, nhân sự không làm việc quan trọng và khẩn cấp trước | I33: Tất cả nhân sự | K33: {=IF($B33="","",IF($A33<>"Có","Không",IF($G33="","Có",IF(IFERROR(INDEX('📚 Bộ câu hỏi'!$A$3:$A1059,MATCH($B33&"|"&$C33&"|",'📚 Bộ câu hỏi'!$L$3:$L1059,0)),"Có")="Không","Không",IF(IFERROR(INDEX('📚 Bộ câu hỏi'!$A$3:$A1059,MATCH($B33&"|"&$C33&"|"&$D33,'📚 Bộ câu hỏi'!$L$3:$L1059,0)),"Có")="Không","Không","Có")))))} -> Có | L33: =IF($B33="","",$B33&"|"&$C33&"|"&$D33) -> Chung||VH5
A34: Có | B34: Chung | D34: VH5 | E34: TIME MANAGEMENT, QUẢN LÝ THỜI GIAN | F34: vi phạm | G34: VH5.3 | H34: Nhân sự hoàn thành công việc trễ hạn | I34: Tất cả nhân sự | K34: {=IF($B34="","",IF($A34<>"Có","Không",IF($G34="","Có",IF(IFERROR(INDEX('📚 Bộ câu hỏi'!$A$3:$A1059,MATCH($B34&"|"&$C34&"|",'📚 Bộ câu hỏi'!$L$3:$L1059,0)),"Có")="Không","Không",IF(IFERROR(INDEX('📚 Bộ câu hỏi'!$A$3:$A1059,MATCH($B34&"|"&$C34&"|"&$D34,'📚 Bộ câu hỏi'!$L$3:$L1059,0)),"Có")="Không","Không","Có")))))} -> Có | L34: =IF($B34="","",$B34&"|"&$C34&"|"&$D34) -> Chung||VH5
A35: Có | B35: Chung | D35: VH5 | E35: TIME MANAGEMENT, QUẢN LÝ THỜI GIAN | F35: vi phạm | G35: VH5.4 | H35: Nhân sự không dành được thời gian cho việc quan trọng nhưng chưa khẩn cấp | I35: Tất cả nhân sự | K35: {=IF($B35="","",IF($A35<>"Có","Không",IF($G35="","Có",IF(IFERROR(INDEX('📚 Bộ câu hỏi'!$A$3:$A1059,MATCH($B35&"|"&$C35&"|",'📚 Bộ câu hỏi'!$L$3:$L1059,0)),"Có")="Không","Không",IF(IFERROR(INDEX('📚 Bộ câu hỏi'!$A$3:$A1059,MATCH($B35&"|"&$C35&"|"&$D35,'📚 Bộ câu hỏi'!$L$3:$L1059,0)),"Có")="Không","Không","Có")))))} -> Có | L35: =IF($B35="","",$B35&"|"&$C35&"|"&$D35) -> Chung||VH5
A36: Có | B36: Chung | D36: VH5 | E36: TIME MANAGEMENT, QUẢN LÝ THỜI GIAN | F36: vi phạm | G36: VH5.5 | H36: Nhân sự để việc quan trọng chưa khẩn cấp trở thành việc khẩn cấp | I36: Tất cả nhân sự | K36: {=IF($B36="","",IF($A36<>"Có","Không",IF($G36="","Có",IF(IFERROR(INDEX('📚 Bộ câu hỏi'!$A$3:$A1059,MATCH($B36&"|"&$C36&"|",'📚 Bộ câu hỏi'!$L$3:$L1059,0)),"Có")="Không","Không",IF(IFERROR(INDEX('📚 Bộ câu hỏi'!$A$3:$A1059,MATCH($B36&"|"&$C36&"|"&$D36,'📚 Bộ câu hỏi'!$L$3:$L1059,0)),"Có")="Không","Không","Có")))))} -> Có | L36: =IF($B36="","",$B36&"|"&$C36&"|"&$D36) -> Chung||VH5
A37: Có | B37: Chung | D37: VH5 | E37: TIME MANAGEMENT, QUẢN LÝ THỜI GIAN | F37: vi phạm | G37: VH5.6 | H37: Cách sắp xếp công việc của nhân sự làm người khác phải xử lý gấp. Không tính việc gấp phát sinh từ nguyên nhân khách quan hoặc thuộc trách nhiệm chung của bộ phận | I37: Tất cả nhân sự | K37: {=IF($B37="","",IF($A37<>"Có","Không",IF($G37="","Có",IF(IFERROR(INDEX('📚 Bộ câu hỏi'!$A$3:$A1059,MATCH($B37&"|"&$C37&"|",'📚 Bộ câu hỏi'!$L$3:$L1059,0)),"Có")="Không","Không",IF(IFERROR(INDEX('📚 Bộ câu hỏi'!$A$3:$A1059,MATCH($B37&"|"&$C37&"|"&$D37,'📚 Bộ câu hỏi'!$L$3:$L1059,0)),"Có")="Không","Không","Có")))))} -> Có | L37: =IF($B37="","",$B37&"|"&$C37&"|"&$D37) -> Chung||VH5
A38: Có | B38: Chung | D38: VH6 | E38: PROACTIVE, TƯ DUY CHỦ ĐỘNG | F38: vi phạm | K38: {=IF($B38="","",IF($A38<>"Có","Không",IF($G38="","Có",IF(IFERROR(INDEX('📚 Bộ câu hỏi'!$A$3:$A1059,MATCH($B38&"|"&$C38&"|",'📚 Bộ câu hỏi'!$L$3:$L1059,0)),"Có")="Không","Không",IF(IFERROR(INDEX('📚 Bộ câu hỏi'!$A$3:$A1059,MATCH($B38&"|"&$C38&"|"&$D38,'📚 Bộ câu hỏi'!$L$3:$L1059,0)),"Có")="Không","Không","Có")))))} -> Có | L38: =IF($B38="","",$B38&"|"&$C38&"|"&$D38) -> Chung||VH6
A39: Có | B39: Chung | D39: VH6 | E39: PROACTIVE, TƯ DUY CHỦ ĐỘNG | F39: vi phạm | G39: VH6.1 | H39: Nhân sự chờ có người nhắc mới bắt đầu việc thuộc phạm vi của mình | I39: Tất cả nhân sự | K39: {=IF($B39="","",IF($A39<>"Có","Không",IF($G39="","Có",IF(IFERROR(INDEX('📚 Bộ câu hỏi'!$A$3:$A1059,MATCH($B39&"|"&$C39&"|",'📚 Bộ câu hỏi'!$L$3:$L1059,0)),"Có")="Không","Không",IF(IFERROR(INDEX('📚 Bộ câu hỏi'!$A$3:$A1059,MATCH($B39&"|"&$C39&"|"&$D39,'📚 Bộ câu hỏi'!$L$3:$L1059,0)),"Có")="Không","Không","Có")))))} -> Có | L39: =IF($B39="","",$B39&"|"&$C39&"|"&$D39) -> Chung||VH6
A40: Có | B40: Chung | D40: VH6 | E40: PROACTIVE, TƯ DUY CHỦ ĐỘNG | F40: vi phạm | G40: VH6.2 | H40: Nhân sự làm việc đối phó: làm cho xong để báo cáo, chỉ làm khi có người kiểm, hoặc làm đúng chữ được giao mà sai mục đích của việc | I40: Tất cả nhân sự | K40: {=IF($B40="","",IF($A40<>"Có","Không",IF($G40="","Có",IF(IFERROR(INDEX('📚 Bộ câu hỏi'!$A$3:$A1059,MATCH($B40&"|"&$C40&"|",'📚 Bộ câu hỏi'!$L$3:$L1059,0)),"Có")="Không","Không",IF(IFERROR(INDEX('📚 Bộ câu hỏi'!$A$3:$A1059,MATCH($B40&"|"&$C40&"|"&$D40,'📚 Bộ câu hỏi'!$L$3:$L1059,0)),"Có")="Không","Không","Có")))))} -> Có | L40: =IF($B40="","",$B40&"|"&$C40&"|"&$D40) -> Chung||VH6
...

Sheet 📊 Điểm nền
A1: 📊 ĐIỂM NỀN ƯỚC TÍNH - Tự tính lại mỗi lần sửa một dòng của sheet 📚 Bộ câu hỏi. Không có ô nào nhập tay ở đây.
B2: Hình dạng phiếu | C2: Điểm nền | D2: Bậc cách làm việc | E2: Ghi chú
B3: Tuyến chưa có ngạch riêng, 6 tuyến | C3: =ROUND(5*(IFERROR((COUNTIFS('📚 Bộ câu hỏi'!$K$3:$K1000,"Có",'📚 Bộ câu hỏi'!$B$3:$B1000,"Chung",'📚 Bộ câu hỏi'!$G$3:$G1000,"<>",'📚 Bộ câu hỏi'!$F$3:$F1000,"vi phạm")-COUNTIFS('📚 Bộ câu hỏi'!$K$3:$K1000,"Có",'📚 Bộ câu hỏi'!$B$3:$B1000,"Chung",'📚 Bộ câu hỏi'!$G$3:$G1000,"<>",'📚 Bộ câu hỏi'!$F$3:$F1000,"vi phạm",'📚 Bộ câu hỏi'!$D$3:$D1000,"VH9")-COUNTIFS('📚 Bộ câu hỏi'!$K$3:$K1000,"Có",'📚 Bộ câu hỏi'!$B$3:$B1000,"Chung",'📚 Bộ câu hỏi'!$G$3:$G1000,"<>",'📚 Bộ câu hỏi'!$F$3:$F1000,"vi phạm",'📚 Bộ câu hỏi'!$D$3:$D1000,"VH10")-COUNTIFS('📚 Bộ câu hỏi'!$K$3:$K1000,"Có",'📚 Bộ câu hỏi'!$B$3:$B1000,"Chung",'📚 Bộ câu hỏi'!$G$3:$G1000,"<>",'📚 Bộ câu hỏi'!$F$3:$F1000,"vi phạm",'📚 Bộ câu hỏi'!$D$3:$D1000,"VH11")-COUNTIFS('📚 Bộ câu hỏi'!$K$3:$K1000,"Có",'📚 Bộ câu hỏi'!$B$3:$B1000,"Chung",'📚 Bộ câu hỏi'!$G$3:$G1000,"<>",'📚 Bộ câu hỏi'!$F$3:$F1000,"vi phạm",'📚 Bộ câu hỏi'!$D$3:$D1000,"VH12")-COUNTIFS('📚 Bộ câu hỏi'!$K$3:$K1000,"Có",'📚 Bộ câu hỏi'!$B$3:$B1000,"Chung",'📚 Bộ câu hỏi'!$G$3:$G1000,"<>",'📚 Bộ câu hỏi'!$F$3:$F1000,"vi phạm",'📚 Bộ câu hỏi'!$D$3:$D1000,"VH13"))/(COUNTIFS('📚 Bộ câu hỏi'!$K$3:$K1000,"Có",'📚 Bộ câu hỏi'!$B$3:$B1000,"Chung",'📚 Bộ câu hỏi'!$G$3:$G1000,"<>")-COUNTIFS('📚 Bộ câu hỏi'!$K$3:$K1000,"Có",'📚 Bộ câu hỏi'!$B$3:$B1000,"Chung",'📚 Bộ câu hỏi'!$G$3:$G1000,"<>",'📚 Bộ câu hỏi'!$D$3:$D1000,"VH9")-COUNTIFS('📚 Bộ câu hỏi'!$K$3:$K1000,"Có",'📚 Bộ câu hỏi'!$B$3:$B1000,"Chung",'📚 Bộ câu hỏi'!$G$3:$G1000,"<>",'📚 Bộ câu hỏi'!$D$3:$D1000,"VH10")-COUNTIFS('📚 Bộ câu hỏi'!$K$3:$K1000,"Có",'📚 Bộ câu hỏi'!$B$3:$B1000,"Chung",'📚 Bộ câu hỏi'!$G$3:$G1000,"<>",'📚 Bộ câu hỏi'!$D$3:$D1000,"VH11")-COUNTIFS('📚 Bộ câu hỏi'!$K$3:$K1000,"Có",'📚 Bộ câu hỏi'!$B$3:$B1000,"Chung",'📚 Bộ câu hỏi'!$G$3:$G1000,"<>",'📚 Bộ câu hỏi'!$D$3:$D1000,"VH12")-COUNTIFS('📚 Bộ câu hỏi'!$K$3:$K1000,"Có",'📚 Bộ câu hỏi'!$B$3:$B1000,"Chung",'📚 Bộ câu hỏi'!$G$3:$G1000,"<>",'📚 Bộ câu hỏi'!$D$3:$D1000,"VH13")),0)),2) -> 4.08 | D3: {=IFERROR(INDEX(NR_NG_BAC,MATCH($C3/5,NR_NG_TL,1)),"")} -> 4
B4: Thương mại & Dịch vụ, nhân viên | C4: =ROUND(5*(TS_TS_VH1*IFERROR((COUNTIFS('📚 Bộ câu hỏi'!$K$3:$K1000,"Có",'📚 Bộ câu hỏi'!$B$3:$B1000,"Chung",'📚 Bộ câu hỏi'!$G$3:$G1000,"<>",'📚 Bộ câu hỏi'!$F$3:$F1000,"vi phạm")-COUNTIFS('📚 Bộ câu hỏi'!$K$3:$K1000,"Có",'📚 Bộ câu hỏi'!$B$3:$B1000,"Chung",'📚 Bộ câu hỏi'!$G$3:$G1000,"<>",'📚 Bộ câu hỏi'!$F$3:$F1000,"vi phạm",'📚 Bộ câu hỏi'!$D$3:$D1000,"TC1"))/(COUNTIFS('📚 Bộ câu hỏi'!$K$3:$K1000,"Có",'📚 Bộ câu hỏi'!$B$3:$B1000,"Chung",'📚 Bộ câu hỏi'!$G$3:$G1000,"<>")-COUNTIFS('📚 Bộ câu hỏi'!$K$3:$K1000,"Có",'📚 Bộ câu hỏi'!$B$3:$B1000,"Chung",'📚 Bộ câu hỏi'!$G$3:$G1000,"<>",'📚 Bộ câu hỏi'!$D$3:$D1000,"TC1")),0)+TS_TS_CM1*IFERROR((COUNTIFS('📚 Bộ câu hỏi'!$K$3:$K1000,"Có",'📚 Bộ câu hỏi'!$B$3:$B1000,"Chuyên môn",'📚 Bộ câu hỏi'!$C$3:$C1000,"Thương mại & Dịch vụ",'📚 Bộ câu hỏi'!$G$3:$G1000,"<>",'📚 Bộ câu hỏi'!$F$3:$F1000,"vi phạm"))/(COUNTIFS('📚 Bộ câu hỏi'!$K$3:$K1000,"Có",'📚 Bộ câu hỏi'!$B$3:$B1000,"Chuyên môn",'📚 Bộ câu hỏi'!$C$3:$C1000,"Thương mại & Dịch vụ",'📚 Bộ câu hỏi'!$G$3:$G1000,"<>")),0)),2) -> 4.52 | D4: {=IFERROR(INDEX(NR_NG_BAC,MATCH($C4/5,NR_NG_TL,1)),"")} -> 5
B5: Thương mại & Dịch vụ, quản lý | C5: =ROUND(5*(TS_TS_VH2*IFERROR((COUNTIFS('📚 Bộ câu hỏi'!$K$3:$K1000,"Có",'📚 Bộ câu hỏi'!$B$3:$B1000,"Chung",'📚 Bộ câu hỏi'!$G$3:$G1000,"<>",'📚 Bộ câu hỏi'!$F$3:$F1000,"vi phạm")-COUNTIFS('📚 Bộ câu hỏi'!$K$3:$K1000,"Có",'📚 Bộ câu hỏi'!$B$3:$B1000,"Chung",'📚 Bộ câu hỏi'!$G$3:$G1000,"<>",'📚 Bộ câu hỏi'!$F$3:$F1000,"vi phạm",'📚 Bộ câu hỏi'!$D$3:$D1000,"TC1"))/(COUNTIFS('📚 Bộ câu hỏi'!$K$3:$K1000,"Có",'📚 Bộ câu hỏi'!$B$3:$B1000,"Chung",'📚 Bộ câu hỏi'!$G$3:$G1000,"<>")-COUNTIFS('📚 Bộ câu hỏi'!$K$3:$K1000,"Có",'📚 Bộ câu hỏi'!$B$3:$B1000,"Chung",'📚 Bộ câu hỏi'!$G$3:$G1000,"<>",'📚 Bộ câu hỏi'!$D$3:$D1000,"TC1")),0)+TS_TS_QL2*IFERROR((COUNTIFS('📚 Bộ câu hỏi'!$K$3:$K1000,"Có",'📚 Bộ câu hỏi'!$B$3:$B1000,"Quản lý",'📚 Bộ câu hỏi'!$C$3:$C1000,"Thương mại & Dịch vụ",'📚 Bộ câu hỏi'!$G$3:$G1000,"<>",'📚 Bộ câu hỏi'!$F$3:$F1000,"vi phạm"))/(COUNTIFS('📚 Bộ câu hỏi'!$K$3:$K1000,"Có",'📚 Bộ câu hỏi'!$B$3:$B1000,"Quản lý",'📚 Bộ câu hỏi'!$C$3:$C1000,"Thương mại & Dịch vụ",'📚 Bộ câu hỏi'!$G$3:$G1000,"<>")),0)+TS_TS_CM2*IFERROR((COUNTIFS('📚 Bộ câu hỏi'!$K$3:$K1000,"Có",'📚 Bộ câu hỏi'!$B$3:$B1000,"Chuyên môn",'📚 Bộ câu hỏi'!$C$3:$C1000,"Thương mại & Dịch vụ",'📚 Bộ câu hỏi'!$G$3:$G1000,"<>",'📚 Bộ câu hỏi'!$F$3:$F1000,"vi phạm"))/(COUNTIFS('📚 Bộ câu hỏi'!$K$3:$K1000,"Có",'📚 Bộ câu hỏi'!$B$3:$B1000,"Chuyên môn",'📚 Bộ câu hỏi'!$C$3:$C1000,"Thương mại & Dịch vụ",'📚 Bộ câu hỏi'!$G$3:$G1000,"<>")),0)),2) -> 4.19 | D5: {=IFERROR(INDEX(NR_NG_BAC,MATCH($C5/5,NR_NG_TL,1)),"")} -> 4
B6: Nhân sự - Hành chính - Pháp chế, nhân viên | C6: =ROUND(5*(TS_TS_VH1*IFERROR((COUNTIFS('📚 Bộ câu hỏi'!$K$3:$K1000,"Có",'📚 Bộ câu hỏi'!$B$3:$B1000,"Chung",'📚 Bộ câu hỏi'!$G$3:$G1000,"<>",'📚 Bộ câu hỏi'!$F$3:$F1000,"vi phạm")-COUNTIFS('📚 Bộ câu hỏi'!$K$3:$K1000,"Có",'📚 Bộ câu hỏi'!$B$3:$B1000,"Chung",'📚 Bộ câu hỏi'!$G$3:$G1000,"<>",'📚 Bộ câu hỏi'!$F$3:$F1000,"vi phạm",'📚 Bộ câu hỏi'!$D$3:$D1000,"VH9")-COUNTIFS('📚 Bộ câu hỏi'!$K$3:$K1000,"Có",'📚 Bộ câu hỏi'!$B$3:$B1000,"Chung",'📚 Bộ câu hỏi'!$G$3:$G1000,"<>",'📚 Bộ câu hỏi'!$F$3:$F1000,"vi phạm",'📚 Bộ câu hỏi'!$D$3:$D1000,"VH10")-COUNTIFS('📚 Bộ câu hỏi'!$K$3:$K1000,"Có",'📚 Bộ câu hỏi'!$B$3:$B1000,"Chung",'📚 Bộ câu hỏi'!$G$3:$G1000,"<>",'📚 Bộ câu hỏi'!$F$3:$F1000,"vi phạm",'📚 Bộ câu hỏi'!$D$3:$D1000,"VH11")-COUNTIFS('📚 Bộ câu hỏi'!$K$3:$K1000,"Có",'📚 Bộ câu hỏi'!$B$3:$B1000,"Chung",'📚 Bộ câu hỏi'!$G$3:$G1000,"<>",'📚 Bộ câu hỏi'!$F$3:$F1000,"vi phạm",'📚 Bộ câu hỏi'!$D$3:$D1000,"VH12")-COUNTIFS('📚 Bộ câu hỏi'!$K$3:$K1000,"Có",'📚 Bộ câu hỏi'!$B$3:$B1000,"Chung",'📚 Bộ câu hỏi'!$G$3:$G1000,"<>",'📚 Bộ câu hỏi'!$F$3:$F1000,"vi phạm",'📚 Bộ câu hỏi'!$D$3:$D1000,"VH13"))/(COUNTIFS('📚 Bộ câu hỏi'!$K$3:$K1000,"Có",'📚 Bộ câu hỏi'!$B$3:$B1000,"Chung",'📚 Bộ câu hỏi'!$G$3:$G1000,"<>")-COUNTIFS('📚 Bộ câu hỏi'!$K$3:$K1000,"Có",'📚 Bộ câu hỏi'!$B$3:$B1000,"Chung",'📚 Bộ câu hỏi'!$G$3:$G1000,"<>",'📚 Bộ câu hỏi'!$D$3:$D1000,"VH9")-COUNTIFS('📚 Bộ câu hỏi'!$K$3:$K1000,"Có",'📚 Bộ câu hỏi'!$B$3:$B1000,"Chung",'📚 Bộ câu hỏi'!$G$3:$G1000,"<>",'📚 Bộ câu hỏi'!$D$3:$D1000,"VH10")-COUNTIFS('📚 Bộ câu hỏi'!$K$3:$K1000,"Có",'📚 Bộ câu hỏi'!$B$3:$B1000,"Chung",'📚 Bộ câu hỏi'!$G$3:$G1000,"<>",'📚 Bộ câu hỏi'!$D$3:$D1000,"VH11")-COUNTIFS('📚 Bộ câu hỏi'!$K$3:$K1000,"Có",'📚 Bộ câu hỏi'!$B$3:$B1000,"Chung",'📚 Bộ câu hỏi'!$G$3:$G1000,"<>",'📚 Bộ câu hỏi'!$D$3:$D1000,"VH12")-COUNTIFS('📚 Bộ câu hỏi'!$K$3:$K1000,"Có",'📚 Bộ câu hỏi'!$B$3:$B1000,"Chung",'📚 Bộ câu hỏi'!$G$3:$G1000,"<>",'📚 Bộ câu hỏi'!$D$3:$D1000,"VH13")),0)+TS_TS_CM1*IFERROR((COUNTIFS('📚 Bộ câu hỏi'!$K$3:$K1000,"Có",'📚 Bộ câu hỏi'!$B$3:$B1000,"Chuyên môn",'📚 Bộ câu hỏi'!$C$3:$C1000,"Nhân sự - Hành chính - Pháp chế",'📚 Bộ câu hỏi'!$G$3:$G1000,"<>",'📚 Bộ câu hỏi'!$F$3:$F1000,"vi phạm"))/(COUNTIFS('📚 Bộ câu hỏi'!$K$3:$K1000,"Có",'📚 Bộ câu hỏi'!$B$3:$B1000,"Chuyên môn",'📚 Bộ câu hỏi'!$C$3:$C1000,"Nhân sự - Hành chính - Pháp chế",'📚 Bộ câu hỏi'!$G$3:$G1000,"<>")),0)),2) -> 4.4 | D6: {=IFERROR(INDEX(NR_NG_BAC,MATCH($C6/5,NR_NG_TL,1)),"")} -> 5
B7: Nhân sự - Hành chính - Pháp chế, quản lý | C7: =ROUND(5*(TS_TS_VH2*IFERROR((COUNTIFS('📚 Bộ câu hỏi'!$K$3:$K1000,"Có",'📚 Bộ câu hỏi'!$B$3:$B1000,"Chung",'📚 Bộ câu hỏi'!$G$3:$G1000,"<>",'📚 Bộ câu hỏi'!$F$3:$F1000,"vi phạm")-COUNTIFS('📚 Bộ câu hỏi'!$K$3:$K1000,"Có",'📚 Bộ câu hỏi'!$B$3:$B1000,"Chung",'📚 Bộ câu hỏi'!$G$3:$G1000,"<>",'📚 Bộ câu hỏi'!$F$3:$F1000,"vi phạm",'📚 Bộ câu hỏi'!$D$3:$D1000,"VH9")-COUNTIFS('📚 Bộ câu hỏi'!$K$3:$K1000,"Có",'📚 Bộ câu hỏi'!$B$3:$B1000,"Chung",'📚 Bộ câu hỏi'!$G$3:$G1000,"<>",'📚 Bộ câu hỏi'!$F$3:$F1000,"vi phạm",'📚 Bộ câu hỏi'!$D$3:$D1000,"VH10")-COUNTIFS('📚 Bộ câu hỏi'!$K$3:$K1000,"Có",'📚 Bộ câu hỏi'!$B$3:$B1000,"Chung",'📚 Bộ câu hỏi'!$G$3:$G1000,"<>",'📚 Bộ câu hỏi'!$F$3:$F1000,"vi phạm",'📚 Bộ câu hỏi'!$D$3:$D1000,"VH11")-COUNTIFS('📚 Bộ câu hỏi'!$K$3:$K1000,"Có",'📚 Bộ câu hỏi'!$B$3:$B1000,"Chung",'📚 Bộ câu hỏi'!$G$3:$G1000,"<>",'📚 Bộ câu hỏi'!$F$3:$F1000,"vi phạm",'📚 Bộ câu hỏi'!$D$3:$D1000,"VH12")-COUNTIFS('📚 Bộ câu hỏi'!$K$3:$K1000,"Có",'📚 Bộ câu hỏi'!$B$3:$B1000,"Chung",'📚 Bộ câu hỏi'!$G$3:$G1000,"<>",'📚 Bộ câu hỏi'!$F$3:$F1000,"vi phạm",'📚 Bộ câu hỏi'!$D$3:$D1000,"VH13"))/(COUNTIFS('📚 Bộ câu hỏi'!$K$3:$K1000,"Có",'📚 Bộ câu hỏi'!$B$3:$B1000,"Chung",'📚 Bộ câu hỏi'!$G$3:$G1000,"<>")-COUNTIFS('📚 Bộ câu hỏi'!$K$3:$K1000,"Có",'📚 Bộ câu hỏi'!$B$3:$B1000,"Chung",'📚 Bộ câu hỏi'!$G$3:$G1000,"<>",'📚 Bộ câu hỏi'!$D$3:$D1000,"VH9")-COUNTIFS('📚 Bộ câu hỏi'!$K$3:$K1000,"Có",'📚 Bộ câu hỏi'!$B$3:$B1000,"Chung",'📚 Bộ câu hỏi'!$G$3:$G1000,"<>",'📚 Bộ câu hỏi'!$D$3:$D1000,"VH10")-COUNTIFS('📚 Bộ câu hỏi'!$K$3:$K1000,"Có",'📚 Bộ câu hỏi'!$B$3:$B1000,"Chung",'📚 Bộ câu hỏi'!$G$3:$G1000,"<>",'📚 Bộ câu hỏi'!$D$3:$D1000,"VH11")-COUNTIFS('📚 Bộ câu hỏi'!$K$3:$K1000,"Có",'📚 Bộ câu hỏi'!$B$3:$B1000,"Chung",'📚 Bộ câu hỏi'!$G$3:$G1000,"<>",'📚 Bộ câu hỏi'!$D$3:$D1000,"VH12")-COUNTIFS('📚 Bộ câu hỏi'!$K$3:$K1000,"Có",'📚 Bộ câu hỏi'!$B$3:$B1000,"Chung",'📚 Bộ câu hỏi'!$G$3:$G1000,"<>",'📚 Bộ câu hỏi'!$D$3:$D1000,"VH13")),0)+TS_TS_QL2*IFERROR((COUNTIFS('📚 Bộ câu hỏi'!$K$3:$K1000,"Có",'📚 Bộ câu hỏi'!$B$3:$B1000,"Quản lý",'📚 Bộ câu hỏi'!$C$3:$C1000,"Nhân sự - Hành chính - Pháp chế",'📚 Bộ câu hỏi'!$G$3:$G1000,"<>",'📚 Bộ câu hỏi'!$F$3:$F1000,"vi phạm"))/(COUNTIFS('📚 Bộ câu hỏi'!$K$3:$K1000,"Có",'📚 Bộ câu hỏi'!$B$3:$B1000,"Quản lý",'📚 Bộ câu hỏi'!$C$3:$C1000,"Nhân sự - Hành chính - Pháp chế",'📚 Bộ câu hỏi'!$G$3:$G1000,"<>")),0)+TS_TS_CM2*IFERROR((COUNTIFS('📚 Bộ câu hỏi'!$K$3:$K1000,"Có",'📚 Bộ câu hỏi'!$B$3:$B1000,"Chuyên môn",'📚 Bộ câu hỏi'!$C$3:$C1000,"Nhân sự - Hành chính - Pháp chế",'📚 Bộ câu hỏi'!$G$3:$G1000,"<>",'📚 Bộ câu hỏi'!$F$3:$F1000,"vi phạm"))/(COUNTIFS('📚 Bộ câu hỏi'!$K$3:$K1000,"Có",'📚 Bộ câu hỏi'!$B$3:$B1000,"Chuyên môn",'📚 Bộ câu hỏi'!$C$3:$C1000,"Nhân sự - Hành chính - Pháp chế",'📚 Bộ câu hỏi'!$G$3:$G1000,"<>")),0)),2) -> 4.54 | D7: {=IFERROR(INDEX(NR_NG_BAC,MATCH($C7/5,NR_NG_TL,1)),"")} -> 5
B8: CHỮ BẬC CHỈ CÒN MỘT NGHĨA: bậc cách làm việc 1 tới 5, thứ tra ra hệ số lương P2 của tháng. Cái từng gọi là "bậc trong ngạch" nay ghi thẳng bằng TÊN CẤP ở cột Phạm vi áp dụng, dạng "Từ Trưởng phòng trở lên", nghĩa là cấp THẤP NHẤT mà câu bắt đầu áp dụng. Các cấp xếp từ thấp lên cao: Tập sự · Nhân viên · Trưởng ca · Lead bộ phận và Chuyên viên ngang nhau · Quản lý khối và Chuyên gia ngang nhau · Trưởng phòng.
B9: Khối trên tính theo tỷ lệ câu của từng phần, đã trừ nhóm mà tuyến không chấm, nhưng chưa trừ phần lọc theo từng người là điểm bán, nhóm ngôn ngữ và ngưỡng cấp, nên lệch vài phần trăm so với con số thật trên phiếu. Ô đỏ nghĩa là hình dạng phiếu đó bắt đầu tháng dưới bậc 4, tức dưới mức Công ty dự định trả.

Sheet 📇 Danh mục tuyến
A1: 📇 DANH MỤC TUYẾN - Thêm tuyến mới: mở Apps Script, thêm một khối vào hằng TUYEN trong 03_DuLieuTuyen, rồi chạy 🔄 Cập nhật phiên bản.
A2: Tuyến | B2: Trạng thái | C2: Ngạch áp dụng | D2: Phạm vi | E2: Kiểu tiêu chí chuyên môn | F2: Các cấp của lưới | G2: Điểm bán | H2: Sheet ma trận
A3: Thương mại & Dịch vụ | B3: ✅ đủ nội dung | C3: chuyên môn + quản lý | D3: Các vị trí tạo ra doanh thu do NGƯỜI TIÊU DÙNG CUỐI chi trả: bán tại Quán, bán trên các sàn thương mại điện tử với tư cách gian hàng chính thức của Công ty, và bán lẻ qua các kênh khác. | E3: 7 tiêu chí độc lập | F3: CM Nhân viên tới Chuyên gia · QL Trưởng ca tới Trưởng phòng | G3: Có | H3: 📐 Thương mại & Dịch vụ
A4: Phát triển Kinh doanh | B4: ⬜ khung rỗng | C4: chuyên môn + quản lý | D4: Các vị trí tự tạo ra nguồn khách hàng, không phụ thuộc lượng khách tự tìm tới Quán hay tới gian hàng trên sàn. | E4: chưa soạn | F4: CM Nhân viên tới Chuyên gia · QL Trưởng ca tới Trưởng phòng | G4: Không | H4: 📐 Phát triển Kinh doanh
A5: Pha chế | B5: ⬜ khung rỗng | C5: chuyên môn + quản lý | D5: Các vị trí pha chế đồ uống tại Quán theo bộ công thức và bộ quy trình pha chế của Công ty. | E5: chưa soạn | F5: CM Nhân viên tới Chuyên gia · QL Trưởng ca tới Trưởng phòng | G5: Có | H5: 📐 Pha chế
A6: Bếp bánh | B6: ⬜ khung rỗng | C6: chuyên môn + quản lý | D6: Các vị trí làm bánh phục vụ tại Quán. | E6: chưa soạn | F6: CM Nhân viên tới Chuyên gia · QL Trưởng ca tới Trưởng phòng | G6: Có | H6: 📐 Bếp bánh
A7: Sản xuất | B7: ⬜ khung rỗng | C7: chuyên môn + quản lý | D7: Các vị trí làm ra sản phẩm của Công ty: tinh dầu, xà phòng, nến thơm, xịt thơm phòng, nước hoa và tinh dầu bi lăn. | E7: chưa soạn | F7: CM Nhân viên tới Chuyên gia · QL Trưởng ca tới Trưởng phòng | G7: Không | H7: 📐 Sản xuất
A8: Kho và Đóng gói | B8: ⬜ khung rỗng | C8: chuyên môn + quản lý | D8: Các vị trí nhận hàng, lưu kho, soạn đơn, đóng gói và giao vận. | E8: chưa soạn | F8: CM Nhân viên tới Chuyên gia · QL Trưởng ca tới Trưởng phòng | G8: Không | H8: 📐 Kho và Đóng gói
A9: Nhân sự - Hành chính - Pháp chế | B9: ⬜ khung rỗng | C9: chuyên môn + quản lý | D9: Các vị trí lo phần con người, phần hành chính và phần pháp chế: tuyển, xếp bậc, đánh giá, điều chuyển, đào tạo văn hóa và đào tạo kỹ năng chung, cơ sở vật chất, văn bản nội bộ, hồ sơ pháp nhân, hợp đồng và tuân thủ. | E9: chưa soạn | F9: CM Nhân viên tới Chuyên gia · QL Trưởng ca tới Trưởng phòng | G9: Không | H9: 📐 Nhân sự - Hành chính - Pháp chế
A10: E-Commerce | B10: ⬜ khung rỗng | C10: chuyên môn + quản lý | D10: Các vị trí vận hành gian hàng của Công ty trên các sàn thương mại điện tử. | E10: chưa soạn | F10: CM Nhân viên tới Chuyên gia · QL Trưởng ca tới Trưởng phòng | G10: Không | H10: 📐 E-Commerce
B12: Tuyến khung rỗng vẫn xuất phiếu được: phần khung chung, ranh giới chung và cách tính đều chạy đủ; riêng phần lưới phân bậc hiện dòng chờ soạn. Làm vậy để bắt đầu chấm phần cách làm việc ngay, không phải chờ soạn xong lưới của mọi tuyến.

Sheet 🎨 Quy ước trình bày
A1: 🎨 QUY ƯỚC TRÌNH BÀY - Mọi phiếu tạo sau đây làm theo bảng này. Sửa trực tiếp ở đây, hoặc chỉnh trên một phiếu rồi chạy 🎨 Học cách trình bày từ một phiếu.
